Workbook
Name Currency: '⚙️ الإعدادات'!$B$17
Name ExpiryWarnDays: '⚙️ الإعدادات'!$B$18
Name GosiCeiling: '⚙️ الإعدادات'!$B$14
Name GosiCoRate: '⚙️ الإعدادات'!$B$13
Name GosiEmpRate: '⚙️ الإعدادات'!$B$12
Name LeaveDaysJunior: '⚙️ الإعدادات'!$B$15
Name LeaveDaysSenior: '⚙️ الإعدادات'!$B$16
Name ListAttState: '⚙️ الإعدادات'!$F$5:$F$9
Name ListContractType: '⚙️ الإعدادات'!$H$5:$H$8
Name ListDepts: '⚙️ الإعدادات'!$D$5:$D$12
Name ListLeaveStatus: '⚙️ الإعدادات'!$I$5:$I$8
Name ListLeaveType: '⚙️ الإعدادات'!$G$5:$G$12
Name ListStatus: '⚙️ الإعدادات'!$E$5:$E$8
Name OTRateHoliday: '⚙️ الإعدادات'!$B$11
Name OTRateRegular: '⚙️ الإعدادات'!$B$10
Name PayMonth: '⚙️ الإعدادات'!$B$4
Name PayPeriod: '⚙️ الإعدادات'!$B$6
Name PayYear: '⚙️ الإعدادات'!$B$5
Name WorkDaysMonth: '⚙️ الإعدادات'!$B$7
Name WorkHoursDay: '⚙️ الإعدادات'!$B$8
Name WorkHoursMonth: '⚙️ الإعدادات'!$B$9

Sheet 🏠 لوحة التحكم
B4: نظام إدارة الموارد البشرية | Q4: HR Management System | 2026
B10: 👥 إجمالي الموظفين | J10: ✅ معدل الحضور | R10: 💰 إجمالي الرواتب
C12: =COUNTA('👥 بيانات الموظفين'!B5:B200) -> 30 | K12: =IFERROR(COUNTIF('📅 الحضور'!E5:E500,"حاضر")/MAX(1,COUNTA('📅 الحضور'!B5:B500)),0) -> 0.84309133 | S12: =IFERROR(SUM('💰 الرواتب'!O5:O204),0) -> 597533.54
C14: مؤشر حي | يتحدث تلقائياً | K14: مؤشر حي | يتحدث تلقائياً | S14: مؤشر حي | يتحدث تلقائياً
B17: 🌴 طلبات إجازة معلقة | J17: 📊 متوسط تقييم الأداء | R17: 🎯 مرشحو التوظيف
C19: =COUNTIF('🌴 الإجازات'!F5:F500,"قيد المراجعة") -> 0 | K19: =IFERROR(AVERAGE('📊 KPI الأداء'!K5:K300),0) -> 85.533333 | S19: =COUNTIF('🎯 التوظيف'!N5:N300,"نشط") -> 0
C21: مؤشر حي | يتحدث تلقائياً | K21: مؤشر حي | يتحدث تلقائياً | S21: مؤشر حي | يتحدث تلقائياً
B26: 📋 توزيع الموظفين والرواتب بالأقسام
B27: القسم | G27: عدد الموظفين | K27: إجمالي الرواتب | O27: متوسط الراتب | S27: نسبة من الكل | W27: مؤشر الأداء
B28: الموارد البشرية | G28: =COUNTIF('👥 بيانات الموظفين'!E5:E200,"الموارد البشرية") -> 2 | K28: =SUMIF('👥 بيانات الموظفين'!E5:E200,"الموارد البشرية",'👥 بيانات الموظفين'!K5:K200) -> 32425 | O28: =IFERROR(SUMIF('👥 بيانات الموظفين'!E5:E200,"الموارد البشرية",'👥 بيانات الموظفين'!K5:K200)/COUNTIF('👥 بيانات الموظفين'!E5:E200,"الموارد البشرية"),0) -> 16212.5 | S28: =IFERROR(COUNTIF('👥 بيانات الموظفين'!E5:E200,"الموارد البشرية")/MAX(1,COUNTA('👥 بيانات الموظفين'!B5:B200)),0) -> 0.066666667 | W28: =IFERROR(AVERAGEIF('📊 KPI الأداء'!D5:D300,"الموارد البشرية",'📊 KPI الأداء'!K5:K300),0) -> 0
B29: المحاسبة | G29: =COUNTIF('👥 بيانات الموظفين'!E5:E200,"المحاسبة") -> 3 | K29: =SUMIF('👥 بيانات الموظفين'!E5:E200,"المحاسبة",'👥 بيانات الموظفين'!K5:K200) -> 45675 | O29: =IFERROR(SUMIF('👥 بيانات الموظفين'!E5:E200,"المحاسبة",'👥 بيانات الموظفين'!K5:K200)/COUNTIF('👥 بيانات الموظفين'!E5:E200,"المحاسبة"),0) -> 15225 | S29: =IFERROR(COUNTIF('👥 بيانات الموظفين'!E5:E200,"المحاسبة")/MAX(1,COUNTA('👥 بيانات الموظفين'!B5:B200)),0) -> 0.1 | W29: =IFERROR(AVERAGEIF('📊 KPI الأداء'!D5:D300,"المحاسبة",'📊 KPI الأداء'!K5:K300),0) -> 0
B30: المبيعات | G30: =COUNTIF('👥 بيانات الموظفين'!E5:E200,"المبيعات") -> 5 | K30: =SUMIF('👥 بيانات الموظفين'!E5:E200,"المبيعات",'👥 بيانات الموظفين'!K5:K200) -> 69750 | O30: =IFERROR(SUMIF('👥 بيانات الموظفين'!E5:E200,"المبيعات",'👥 بيانات الموظفين'!K5:K200)/COUNTIF('👥 بيانات الموظفين'!E5:E200,"المبيعات"),0) -> 13950 | S30: =IFERROR(COUNTIF('👥 بيانات الموظفين'!E5:E200,"المبيعات")/MAX(1,COUNTA('👥 بيانات الموظفين'!B5:B200)),0) -> 0.16666667 | W30: =IFERROR(AVERAGEIF('📊 KPI الأداء'!D5:D300,"المبيعات",'📊 KPI الأداء'!K5:K300),0) -> 0
B31: خدمة العملاء | G31: =COUNTIF('👥 بيانات الموظفين'!E5:E200,"خدمة العملاء") -> 4 | K31: =SUMIF('👥 بيانات الموظفين'!E5:E200,"خدمة العملاء",'👥 بيانات الموظفين'!K5:K200) -> 38025 | O31: =IFERROR(SUMIF('👥 بيانات الموظفين'!E5:E200,"خدمة العملاء",'👥 بيانات الموظفين'!K5:K200)/COUNTIF('👥 بيانات الموظفين'!E5:E200,"خدمة العملاء"),0) -> 9506.25 | S31: =IFERROR(COUNTIF('👥 بيانات الموظفين'!E5:E200,"خدمة العملاء")/MAX(1,COUNTA('👥 بيانات الموظفين'!B5:B200)),0) -> 0.13333333 | W31: =IFERROR(AVERAGEIF('📊 KPI الأداء'!D5:D300,"خدمة العملاء",'📊 KPI الأداء'!K5:K300),0) -> 0
B32: تقنية المعلومات | G32: =COUNTIF('👥 بيانات الموظفين'!E5:E200,"تقنية المعلومات") -> 8 | K32: =SUMIF('👥 بيانات الموظفين'!E5:E200,"تقنية المعلومات",'👥 بيانات الموظفين'!K5:K200) -> 149025 | O32: =IFERROR(SUMIF('👥 بيانات الموظفين'!E5:E200,"تقنية المعلومات",'👥 بيانات الموظفين'!K5:K200)/COUNTIF('👥 بيانات الموظفين'!E5:E200,"تقنية المعلومات"),0) -> 18628.125 | S32: =IFERROR(COUNTIF('👥 بيانات الموظفين'!E5:E200,"تقنية المعلومات")/MAX(1,COUNTA('👥 بيانات الموظفين'!B5:B200)),0) -> 0.26666667 | W32: =IFERROR(AVERAGEIF('📊 KPI الأداء'!D5:D300,"تقنية المعلومات",'📊 KPI الأداء'!K5:K300),0) -> 0
B33: العمليات | G33: =COUNTIF('👥 بيانات الموظفين'!E5:E200,"العمليات") -> 2 | K33: =SUMIF('👥 بيانات الموظفين'!E5:E200,"العمليات",'👥 بيانات الموظفين'!K5:K200) -> 31075 | O33: =IFERROR(SUMIF('👥 بيانات الموظفين'!E5:E200,"العمليات",'👥 بيانات الموظفين'!K5:K200)/COUNTIF('👥 بيانات الموظفين'!E5:E200,"العمليات"),0) -> 15537.5 | S33: =IFERROR(COUNTIF('👥 بيانات الموظفين'!E5:E200,"العمليات")/MAX(1,COUNTA('👥 بيانات الموظفين'!B5:B200)),0) -> 0.066666667 | W33: =IFERROR(AVERAGEIF('📊 KPI الأداء'!D5:D300,"العمليات",'📊 KPI الأداء'!K5:K300),0) -> 0
B34: التسويق | G34: =COUNTIF('👥 بيانات الموظفين'!E5:E200,"التسويق") -> 3 | K34: =SUMIF('👥 بيانات الموظفين'!E5:E200,"التسويق",'👥 بيانات الموظفين'!K5:K200) -> 48375 | O34: =IFERROR(SUMIF('👥 بيانات الموظفين'!E5:E200,"التسويق",'👥 بيانات الموظفين'!K5:K200)/COUNTIF('👥 بيانات الموظفين'!E5:E200,"التسويق"),0) -> 16125 | S34: =IFERROR(COUNTIF('👥 بيانات الموظفين'!E5:E200,"التسويق")/MAX(1,COUNTA('👥 بيانات الموظفين'!B5:B200)),0) -> 0.1 | W34: =IFERROR(AVERAGEIF('📊 KPI الأداء'!D5:D300,"التسويق",'📊 KPI الأداء'!K5:K300),0) -> 0
B35: الإدارة | G35: =COUNTIF('👥 بيانات الموظفين'!E5:E200,"الإدارة") -> 3 | K35: =SUMIF('👥 بيانات الموظفين'!E5:E200,"الإدارة",'👥 بيانات الموظفين'!K5:K200) -> 140050 | O35: =IFERROR(SUMIF('👥 بيانات الموظفين'!E5:E200,"الإدارة",'👥 بيانات الموظفين'!K5:K200)/COUNTIF('👥 بيانات الموظفين'!E5:E200,"الإدارة"),0) -> 46683.333 | S35: =IFERROR(COUNTIF('👥 بيانات الموظفين'!E5:E200,"الإدارة")/MAX(1,COUNTA('👥 بيانات الموظفين'!B5:B200)),0) -> 0.1 | W35: =IFERROR(AVERAGEIF('📊 KPI الأداء'!D5:D300,"الإدارة",'📊 KPI الأداء'!K5:K300),0) -> 0
B36: الإجمالي | G36: =COUNTA('👥 بيانات الموظفين'!B5:B200) -> 30 | K36: =IFERROR(SUM('👥 بيانات الموظفين'!K5:K200),0) -> 554400 | O36: 100%
B39: 🔗 انتقل إلى — التنقل السريع بين أوراق النظام
B42: 👥 بيانات الموظفين | H42: 📅 الحضور | N42: 💰 الرواتب | T42: 🌴 الإجازات
B43: قاعدة بيانات الموظفين | H43: سجل الحضور اليومي | N43: كشف الرواتب الشهري | T43: إدارة الإجازات
B47: ➕ الخصومات | H47: 📊 KPI الأداء | N47: 🎯 التوظيف | T47: 📈 التقارير
B48: الخصومات والمكافآت | H48: مؤشرات الأداء | N48: مسار التوظيف | T48: التقارير والتحليلات
A65: 🚨 تنبيهات حرجة
A66: تتحدث تلقائياً من بيانات الموظفين والحضور
A67: البند | B67: العدد | C67: ملاحظة
A68: 🆔 إقامات تنتهي خلال 60 يوم | B68: =SUMPRODUCT(('👥 بيانات الموظفين'!$X$5:$X$204<>"")*('👥 بيانات الموظفين'!$X$5:$X$204-TODAY()<=ExpiryWarnDays)*('👥 بيانات الموظفين'!$X$5:$X$204-TODAY()>=0)) -> 2 | C68: تواصل مع الجوازات / مكتب العمل
A69: 📜 عقود تنتهي خلال 60 يوم | B69: =SUMPRODUCT(('👥 بيانات الموظفين'!$V$5:$V$204<>"")*('👥 بيانات الموظفين'!$V$5:$V$204-TODAY()<=ExpiryWarnDays)*('👥 بيانات الموظفين'!$V$5:$V$204-TODAY()>=0)) -> 1 | C69: ابدأ إجراءات التجديد
A70: 🟡 فترات تجربة تنتهي خلال 30 يوم | B70: =SUMPRODUCT(('👥 بيانات الموظفين'!$W$5:$W$204<>"")*('👥 بيانات الموظفين'!$W$5:$W$204-TODAY()<=30)*('👥 بيانات الموظفين'!$W$5:$W$204-TODAY()>=0)) -> 0 | C70: اتخاذ قرار التثبيت أو الإنهاء
A71: 🌴 موظفون رصيد إجازتهم سالب | B71: =SUMPRODUCT(('👥 بيانات الموظفين'!$Q$5:$Q$204<0)*1) -> 1 | C71: مراجعة سجل الإجازات
A72: ❌ غيابات بدون إذن هذا الشهر | B72: =COUNTIFS('📅 الحضور'!$E:$E,"غائب",'📅 الحضور'!$L:$L,PayPeriod) -> 3 | C72: إجراء تأديبي محتمل

Sheet ⚙️ الإعدادات
A1: ⚙️ إعدادات النظام
A2: Source-of-truth — كل صيغ النظام تقرأ من هنا
D3: قوائم القيم
A4: شهر التشغيل (1-12) | B4: 4 | D4: الأقسام | E4: حالة الموظف | F4: حالة الحضور | G4: نوع الإجازة | H4: نوع العقد | I4: حالة الإجازة
A5: سنة التشغيل | B5: 2026 | D5: الموارد البشرية | E5: نشط | F5: حاضر | G5: سنوية | H5: دائم | I5: قيد المراجعة
A6: فترة التشغيل (شهر-سنة) | B6: =TEXT(DATE(B5,B4,1),"yyyy-mm") -> 2026-04 | D6: المحاسبة | E6: موقوف | F6: متأخر | G6: مرضية | H6: محدد المدة | I6: معتمدة
A7: أيام العمل في الشهر | B7: 30 | D7: المبيعات | E7: إجازة بدون راتب | F7: غائب | G7: اضطرارية | H7: تجربة | I7: مرفوضة
A8: ساعات العمل اليومية | B8: 8 | D8: خدمة العملاء | E8: منتهي الخدمة | F8: إجازة | G8: أمومة | H8: موسمي | I8: ملغاة
A9: ساعات الشهر القياسية | B9: =B7*B8 -> 240 | D9: تقنية المعلومات | F9: عطلة رسمية | G9: حج
A10: نسبة OT العادي | B10: 1.5 | D10: العمليات | G10: زواج
A11: نسبة OT العطل/الجمعة | B11: 2 | D11: التسويق | G11: وفاة
A12: GOSI - حصة الموظف (سعودي) | B12: 0.1 | D12: الإدارة | G12: بدون راتب
A13: GOSI - حصة الشركة (سعودي) | B13: 0.12
A14: GOSI - الحد الأعلى (ريال) | B14: 45000
A15: إجازة سنوية - أول 5 سنوات | B15: 21
A16: إجازة سنوية - بعد 5 سنوات | B16: 30
A17: العملة | B17: ريال
A18: تحذير انتهاء (يوم) | B18: 60

Sheet 👥 بيانات الموظفين
A1: 👥 قاعدة بيانات الموظفين
A2: Employee Database — يتم تحديثها تلقائياً مع باقي الأوراق
A4: م | B4: رقم الموظف | C4: الاسم الكامل | D4: الجنسية | E4: القسم | F4: المسمى الوظيفي | G4: الحالة | H4: الراتب الأساسي | I4: بدل السكن | J4: بدل النقل | K4: إجمالي الراتب | L4: تاريخ التعيين | M4: سنوات الخدمة | N4: رقم الهوية | O4: رقم الجوال | P4: البريد الإلكتروني | Q4: رصيد الإجازة | R4: المدير المباشر | S4: ملاحظات | T4: نوع العقد | U4: بداية العقد | V4: نهاية العقد | W4: نهاية فترة التجربة | X4: تاريخ انتهاء الإقامة | Y4: رقم GOSI | Z4: IBAN | AA4: التأمين الطبي | AB4: EOSB المستحقة | AC4: إجازة سنوية مستحقة | AD4: تنبيه
A5: 1 | B5: EMP001 | C5: عبدالعزيز محمد العتيبي | D5: سعودي | E5: الإدارة | F5: الرئيس التنفيذي | G5: نشط | H5: 42000 | I5: 10500 | J5: 2500 | K5: =H5+I5+J5 -> 55000 | L5: =DATEVALUE("2017-01-15") -> 42750 | M5: =IF(L5<>"",DATEDIF(L5,TODAY(),"Y"),"") -> 9 | N5: 1023456789 | O5: 501112222 | P5: aziz.alotaibi@techvision.sa | Q5: =IF(B5="","",AC5-IFERROR(SUMIFS('🌴 الإجازات'!$G:$G,'🌴 الإجازات'!$B:$B,B5,'🌴 الإجازات'!$K:$K,"معتمدة"),0)) -> 30 | R5: مجلس الإدارة | S5: مؤسس مشارك | T5: دائم | U5: =DATEVALUE("2017-01-15") -> 42750 | Y5: 100200300401 | Z5: SA0312345678901234567890 | AA5: بوبا - VIP بلاتينيوم | AB5: =IF(AND(B5<>"",L5<>""),(0.5*H5*MIN(M5,5))+(1*H5*MAX(0,M5-5)),"") -> 273000 | AC5: =IF(B5<>"",IF(IFERROR(M5,0)>=5,LeaveDaysSenior,LeaveDaysJunior),"") -> 30 | AD5: =IF(B5="","",IF(AND(X5<>"",X5-TODAY()<=ExpiryWarnDays,X5-TODAY()>=0),"⚠️ إقامة تنتهي خلال "&(X5-TODAY())&" يوم",IF(AND(V5<>"",V5-TODAY()<=ExpiryWarnDays,V5-TODAY()>=0),"⚠️ عقد ينتهي خلال "&(V5-TODAY())&" يوم",IF(AND(W5<>"",W5-TODAY()<=30,W5-TODAY()>=0),"🟡 تجربة تنتهي خلال "&(W5-TODAY())&" يوم",""))))
A6: 2 | B6: EMP002 | C6: فاطمة سعد الزهراني | D6: سعودية | E6: الإدارة | F6: الرئيس التنفيذي للعمليات | G6: نشط | H6: 35000 | I6: 8750 | J6: 2000 | K6: =H6+I6+J6 -> 45750 | L6: =DATEVALUE("2018-06-01") -> 43252 | M6: =IF(L6<>"",DATEDIF(L6,TODAY(),"Y"),"") -> 7 | N6: 2034567890 | O6: 552223333 | P6: fatima.alzahrani@techvision.sa | Q6: =IF(B6="","",AC6-IFERROR(SUMIFS('🌴 الإجازات'!$G:$G,'🌴 الإجازات'!$B:$B,B6,'🌴 الإجازات'!$K:$K,"معتمدة"),0)) -> 30 | R6: عبدالعزيز العتيبي | T6: دائم | U6: =DATEVALUE("2018-06-01") -> 43252 | Y6: 100200300402 | Z6: SA0398765432109876543210 | AA6: بوبا - VIP بلاتينيوم | AB6: =IF(AND(B6<>"",L6<>""),(0.5*H6*MIN(M6,5))+(1*H6*MAX(0,M6-5)),"") -> 157500 | AC6: =IF(B6<>"",IF(IFERROR(M6,0)>=5,LeaveDaysSenior,LeaveDaysJunior),"") -> 30 | AD6: =IF(B6="","",IF(AND(X6<>"",X6-TODAY()<=ExpiryWarnDays,X6-TODAY()>=0),"⚠️ إقامة تنتهي خلال "&(X6-TODAY())&" يوم",IF(AND(V6<>"",V6-TODAY()<=ExpiryWarnDays,V6-TODAY()>=0),"⚠️ عقد ينتهي خلال "&(V6-TODAY())&" يوم",IF(AND(W6<>"",W6-TODAY()<=30,W6-TODAY()>=0),"🟡 تجربة تنتهي خلال "&(W6-TODAY())&" يوم",""))))
A7: 3 | B7: EMP003 | C7: خالد عبدالرحمن الدوسري | D7: سعودي | E7: الإدارة | F7: الرئيس التنفيذي للمالية | G7: نشط | H7: 30000 | I7: 7500 | J7: 1800 | K7: =H7+I7+J7 -> 39300 | L7: =DATEVALUE("2019-03-10") -> 43534 | M7: =IF(L7<>"",DATEDIF(L7,TODAY(),"Y"),"") -> 7 | N7: 1045678901 | O7: 533334444 | P7: khalid.aldosari@techvision.sa | Q7: =IF(B7="","",AC7-IFERROR(SUMIFS('🌴 الإجازات'!$G:$G,'🌴 الإجازات'!$B:$B,B7,'🌴 الإجازات'!$K:$K,"معتمدة"),0)) -> 30 | R7: عبدالعزيز العتيبي | T7: دائم | U7: =DATEVALUE("2019-03-10") -> 43534 | Y7: 100200300403 | Z7: SA0311112222333344445555 | AA7: بوبا - VIP | AB7: =IF(AND(B7<>"",L7<>""),(0.5*H7*MIN(M7,5))+(1*H7*MAX(0,M7-5)),"") -> 135000 | AC7: =IF(B7<>"",IF(IFERROR(M7,0)>=5,LeaveDaysSenior,LeaveDaysJunior),"") -> 30 | AD7: =IF(B7="","",IF(AND(X7<>"",X7-TODAY()<=ExpiryWarnDays,X7-TODAY()>=0),"⚠️ إقامة تنتهي خلال "&(X7-TODAY())&" يوم",IF(AND(V7<>"",V7-TODAY()<=ExpiryWarnDays,V7-TODAY()>=0),"⚠️ عقد ينتهي خلال "&(V7-TODAY())&" يوم",IF(AND(W7<>"",W7-TODAY()<=30,W7-TODAY()>=0),"🟡 تجربة تنتهي خلال "&(W7-TODAY())&" يوم",""))))
A8: 4 | B8: EMP004 | C8: سلطان فيصل القحطاني | D8: سعودي | E8: تقنية المعلومات | F8: الرئيس التقني | G8: نشط | H8: 28000 | I8: 7000 | J8: 1500 | K8: =H8+I8+J8 -> 36500 | L8: =DATEVALUE("2018-09-15") -> 43358 | M8: =IF(L8<>"",DATEDIF(L8,TODAY(),"Y"),"") -> 7 | N8: 1056789012 | O8: 544445555 | P8: sultan.alqahtani@techvision.sa | Q8: =IF(B8="","",AC8-IFERROR(SUMIFS('🌴 الإجازات'!$G:$G,'🌴 الإجازات'!$B:$B,B8,'🌴 الإجازات'!$K:$K,"معتمدة"),0)) -> 19 | R8: عبدالعزيز العتيبي | T8: دائم | U8: =DATEVALUE("2018-09-15") -> 43358 | Y8: 100200300404 | Z8: SA0399998888777766665555 | AA8: بوبا - VIP | AB8: =IF(AND(B8<>"",L8<>""),(0.5*H8*MIN(M8,5))+(1*H8*MAX(0,M8-5)),"") -> 126000 | AC8: =IF(B8<>"",IF(IFERROR(M8,0)>=5,LeaveDaysSenior,LeaveDaysJunior),"") -> 30 | AD8: =IF(B8="","",IF(AND(X8<>"",X8-TODAY()<=ExpiryWarnDays,X8-TODAY()>=0),"⚠️ إقامة تنتهي خلال "&(X8-TODAY())&" يوم",IF(AND(V8<>"",V8-TODAY()<=ExpiryWarnDays,V8-TODAY()>=0),"⚠️ عقد ينتهي خلال "&(V8-TODAY())&" يوم",IF(AND(W8<>"",W8-TODAY()<=30,W8-TODAY()>=0),"🟡 تجربة تنتهي خلال "&(W8-TODAY())&" يوم",""))))
A9: 5 | B9: EMP005 | C9: Rajesh Kumar Sharma | D9: هندي | E9: تقنية المعلومات | F9: مهندس برمجيات أول | G9: نشط | H9: 18000 | I9: 4500 | J9: 1000 | K9: =H9+I9+J9 -> 23500 | L9: =DATEVALUE("2020-02-20") -> 43881 | M9: =IF(L9<>"",DATEDIF(L9,TODAY(),"Y"),"") -> 6 | N9: 2456789012345 | O9: 555556666 | P9: rajesh.sharma@techvision.sa | Q9: =IF(B9="","",AC9-IFERROR(SUMIFS('🌴 الإجازات'!$G:$G,'🌴 الإجازات'!$B:$B,B9,'🌴 الإجازات'!$K:$K,"معتمدة"),0)) -> 30 | R9: سلطان القحطاني | S9: إقامة تنتهي قريباً | T9: دائم | U9: =DATEVALUE("2020-02-20") -> 43881 | X9: =DATEVALUE("2026-06-15") -> 46188 | Z9: SA0344445555666677778888 | AA9: ميدغلف - بلاتينيوم | AB9: =IF(AND(B9<>"",L9<>""),(0.5*H9*MIN(M9,5))+(1*H9*MAX(0,M9-5)),"") -> 63000 | AC9: =IF(B9<>"",IF(IFERROR(M9,0)>=5,LeaveDaysSenior,LeaveDaysJunior),"") -> 30 | AD9: =IF(B9="","",IF(AND(X9<>"",X9-TODAY()<=ExpiryWarnDays,X9-TODAY()>=0),"⚠️ إقامة تنتهي خلال "&(X9-TODAY())&" يوم",IF(AND(V9<>"",V9-TODAY()<=ExpiryWarnDays,V9-TODAY()>=0),"⚠️ عقد ينتهي خلال "&(V9-TODAY())&" يوم",IF(AND(W9<>"",W9-TODAY()<=30,W9-TODAY()>=0),"🟡 تجربة تنتهي خلال "&(W9-TODAY())&" يوم","")))) -> ⚠️ إقامة تنتهي خلال 42 يوم
A10: 6 | B10: EMP006 | C10: Mohamed Ahmed Hassan | D10: مصري | E10: تقنية المعلومات | F10: مهندس DevOps | G10: نشط | H10: 15000 | I10: 3750 | J10: 1000 | K10: =IF(H10<>"",H10+I10+J10,"") -> 19750 | L10: =DATEVALUE("2021-04-12") -> 44298 | M10: =IF(L10<>"",DATEDIF(L10,TODAY(),"Y"),"") -> 5 | N10: 2567890123456 | O10: 566667777 | P10: mohamed.hassan@techvision.sa | Q10: =IF(B10="","",AC10-IFERROR(SUMIFS('🌴 الإجازات'!$G:$G,'🌴 الإجازات'!$B:$B,B10,'🌴 الإجازات'!$K:$K,"معتمدة"),0)) -> 30 | R10: سلطان القحطاني | T10: دائم | U10: =DATEVALUE("2021-04-12") -> 44298 | X10: =DATEVALUE("2027-03-20") -> 46466 | Z10: SA0355556666777788889999 | AA10: ميدغلف - VIP | AB10: =IF(AND(B10<>"",L10<>""),(0.5*H10*MIN(M10,5))+(1*H10*MAX(0,M10-5)),"") -> 37500 | AC10: =IF(B10<>"",IF(IFERROR(M10,0)>=5,LeaveDaysSenior,LeaveDaysJunior),"") -> 30 | AD10: =IF(B10="","",IF(AND(X10<>"",X10-TODAY()<=ExpiryWarnDays,X10-TODAY()>=0),"⚠️ إقامة تنتهي خلال "&(X10-TODAY())&" يوم",IF(AND(V10<>"",V10-TODAY()<=ExpiryWarnDays,V10-TODAY()>=0),"⚠️ عقد ينتهي خلال "&(V10-TODAY())&" يوم",IF(AND(W10<>"",W10-TODAY()<=30,W10-TODAY()>=0),"🟡 تجربة تنتهي خلال "&(W10-TODAY())&" يوم",""))))
A11: 7 | B11: EMP007 | C11: نورة عبدالله الشمري | D11: سعودية | E11: تقنية المعلومات | F11: مهندسة برمجيات | G11: نشط | H11: 12000 | I11: 3000 | J11: 800 | K11: =IF(H11<>"",H11+I11+J11,"") -> 15800 | L11: =DATEVALUE("2022-08-01") -> 44774 | M11: =IF(L11<>"",DATEDIF(L11,TODAY(),"Y"),"") -> 3 | N11: 2078901234 | O11: 577778888 | P11: noura.alshamri@techvision.sa | Q11: =IF(B11="","",AC11-IFERROR(SUMIFS('🌴 الإجازات'!$G:$G,'🌴 الإجازات'!$B:$B,B11,'🌴 الإجازات'!$K:$K,"معتمدة"),0)) -> -44 | R11: سلطان القحطاني | S11: عائدة من إجازة أمومة | T11: دائم | U11: =DATEVALUE("2022-08-01") -> 44774 | Y11: 100200300407 | Z11: SA0366667777888899990000 | AA11: بوبا - VIP | AB11: =IF(AND(B11<>"",L11<>""),(0.5*H11*MIN(M11,5))+(1*H11*MAX(0,M11-5)),"") -> 18000 | AC11: =IF(B11<>"",IF(IFERROR(M11,0)>=5,LeaveDaysSenior,LeaveDaysJunior),"") -> 21 | AD11: =IF(B11="","",IF(AND(X11<>"",X11-TODAY()<=ExpiryWarnDays,X11-TODAY()>=0),"⚠️ إقامة تنتهي خلال "&(X11-TODAY())&" يوم",IF(AND(V11<>"",V11-TODAY()<=ExpiryWarnDays,V11-TODAY()>=0),"⚠️ عقد ينتهي خلال "&(V11-TODAY())&" يوم",IF(AND(W11<>"",W11-TODAY()<=30,W11-TODAY()>=0),"🟡 تجربة تنتهي خلال "&(W11-TODAY())&" يوم",""))))
A12: 8 | B12: EMP008 | C12: عبدالرحمن خالد المالكي | D12: سعودي | E12: تقنية المعلومات | F12: مهندس بيانات | G12: نشط | H12: 14000 | I12: 3500 | J12: 900 | K12: =IF(H12<>"",H12+I12+J12,"") -> 18400 | L12: =DATEVALUE("2022-11-05") -> 44870 | M12: =IF(L12<>"",DATEDIF(L12,TODAY(),"Y"),"") -> 3 | N12: 1089012345 | O12: 588889999 | P12: abdulrahman.almaliki@techvision.sa | Q12: =IF(B12="","",AC12-IFERROR(SUMIFS('🌴 الإجازات'!$G:$G,'🌴 الإجازات'!$B:$B,B12,'🌴 الإجازات'!$K:$K,"معتمدة"),0)) -> 19 | R12: سلطان القحطاني | T12: دائم | U12: =DATEVALUE("2022-11-05") -> 44870 | Y12: 100200300408 | Z12: SA0377778888999900001111 | AA12: بوبا - VIP | AB12: =IF(AND(B12<>"",L12<>""),(0.5*H12*MIN(M12,5))+(1*H12*MAX(0,M12-5)),"") -> 21000 | AC12: =IF(B12<>"",IF(IFERROR(M12,0)>=5,LeaveDaysSenior,LeaveDaysJunior),"") -> 21 | AD12: =IF(B12="","",IF(AND(X12<>"",X12-TODAY()<=ExpiryWarnDays,X12-TODAY()>=0),"⚠️ إقامة تنتهي خلال "&(X12-TODAY())&" يوم",IF(AND(V12<>"",V12-TODAY()<=ExpiryWarnDays,V12-TODAY()>=0),"⚠️ عقد ينتهي خلال "&(V12-TODAY())&" يوم",IF(AND(W12<>"",W12-TODAY()<=30,W12-TODAY()>=0),"🟡 تجربة تنتهي خلال "&(W12-TODAY())&" يوم",""))))
A13: 9 | B13: EMP009 | C13: Ali Hassan Khan | D13: باكستاني | E13: تقنية المعلومات | F13: مهندس Frontend | G13: نشط | H13: 11000 | I13: 2750 | J13: 750 | K13: =IF(H13<>"",H13+I13+J13,"") -> 14500 | L13: =DATEVALUE("2024-01-10") -> 45301 | M13: =IF(L13<>"",DATEDIF(L13,TODAY(),"Y"),"") -> 2 | N13: 2678901234567 | O13: 599990000 | P13: ali.khan@techvision.sa | Q13: =IF(B13="","",AC13-IFERROR(SUMIFS('🌴 الإجازات'!$G:$G,'🌴 الإجازات'!$B:$B,B13,'🌴 الإجازات'!$K:$K,"معتمدة"),0)) -> 21 | R13: سلطان القحطاني | T13: محدد المدة | U13: =DATEVALUE("2024-01-10") -> 45301 | V13: =DATEVALUE("2027-01-09") -> 46396 | X13: =DATEVALUE("2026-08-25") -> 46259 | Z13: SA0388889999000011112222 | AA13: ميدغلف - فضي | AB13: =IF(AND(B13<>"",L13<>""),(0.5*H13*MIN(M13,5))+(1*H13*MAX(0,M13-5)),"") -> 11000 | AC13: =IF(B13<>"",IF(IFERROR(M13,0)>=5,LeaveDaysSenior,LeaveDaysJunior),"") -> 21 | AD13: =IF(B13="","",IF(AND(X13<>"",X13-TODAY()<=ExpiryWarnDays,X13-TODAY()>=0),"⚠️ إقامة تنتهي خلال "&(X13-TODAY())&" يوم",IF(AND(V13<>"",V13-TODAY()<=ExpiryWarnDays,V13-TODAY()>=0),"⚠️ عقد ينتهي خلال "&(V13-TODAY())&" يوم",IF(AND(W13<>"",W13-TODAY()<=30,W13-TODAY()>=0),"🟡 تجربة تنتهي خلال "&(W13-TODAY())&" يوم",""))))
A14: 10 | B14: EMP010 | C14: ريم سعود العنزي | D14: سعودية | E14: تقنية المعلومات | F14: مهندسة QA | G14: نشط | H14: 9000 | I14: 2250 | J14: 700 | K14: =IF(H14<>"",H14+I14+J14,"") -> 11950 | L14: =DATEVALUE("2024-09-15") -> 45550 | M14: =IF(L14<>"",DATEDIF(L14,TODAY(),"Y"),"") -> 1 | N14: 2090123456 | O14: 501230001 | P14: reem.alanazi@techvision.sa | Q14: =IF(B14="","",AC14-IFERROR(SUMIFS('🌴 الإجازات'!$G:$G,'🌴 الإجازات'!$B:$B,B14,'🌴 الإجازات'!$K:$K,"معتمدة"),0)) -> 19 | R14: سلطان القحطاني | T14: دائم | U14: =DATEVALUE("2024-09-15") -> 45550 | Y14: 100200300410 | Z14: SA0399990000111122223333 | AA14: بوبا - فضي | AB14: =IF(AND(B14<>"",L14<>""),(0.5*H14*MIN(M14,5))+(1*H14*MAX(0,M14-5)),"") -> 4500 | AC14: =IF(B14<>"",IF(IFERROR(M14,0)>=5,LeaveDaysSenior,LeaveDaysJunior),"") -> 21 | AD14: =IF(B14="","",IF(AND(X14<>"",X14-TODAY()<=ExpiryWarnDays,X14-TODAY()>=0),"⚠️ إقامة تنتهي خلال "&(X14-TODAY())&" يوم",IF(AND(V14<>"",V14-TODAY()<=ExpiryWarnDays,V14-TODAY()>=0),"⚠️ عقد ينتهي خلال "&(V14-TODAY())&" يوم",IF(AND(W14<>"",W14-TODAY()<=30,W14-TODAY()>=0),"🟡 تجربة تنتهي خلال "&(W14-TODAY())&" يوم",""))))
A15: 11 | B15: EMP011 | C15: فهد عبدالله الشهري | D15: سعودي | E15: تقنية المعلومات | F15: مطور Junior | G15: نشط | H15: 6500 | I15: 1625 | J15: 500 | K15: =IF(H15<>"",H15+I15+J15,"") -> 8625 | L15: =DATEVALUE("2026-02-01") -> 46054 | M15: =IF(L15<>"",DATEDIF(L15,TODAY(),"Y"),"") -> 0 | N15: 1101234567 | O15: 501230002 | P15: fahd.alshehri@techvision.sa | Q15: =IF(B15="","",AC15-IFERROR(SUMIFS('🌴 الإجازات'!$G:$G,'🌴 الإجازات'!$B:$B,B15,'🌴 الإجازات'!$K:$K,"معتمدة"),0)) -> 21 | R15: سلطان القحطاني | S15: موظف جديد - فترة تجربة | T15: تجربة | U15: =DATEVALUE("2026-02-01") -> 46054 | W15: =DATEVALUE("2026-05-01") -> 46143 | Y15: 100200300411 | Z15: SA0300001111222233334444 | AA15: بوبا - فضي | AB15: =IF(AND(B15<>"",L15<>""),(0.5*H15*MIN(M15,5))+(1*H15*MAX(0,M15-5)),"") -> 0 | AC15: =IF(B15<>"",IF(IFERROR(M15,0)>=5,LeaveDaysSenior,LeaveDaysJunior),"") -> 21 | AD15: =IF(B15="","",IF(AND(X15<>"",X15-TODAY()<=ExpiryWarnDays,X15-TODAY()>=0),"⚠️ إقامة تنتهي خلال "&(X15-TODAY())&" يوم",IF(AND(V15<>"",V15-TODAY()<=ExpiryWarnDays,V15-TODAY()>=0),"⚠️ عقد ينتهي خلال "&(V15-TODAY())&" يوم",IF(AND(W15<>"",W15-TODAY()<=30,W15-TODAY()>=0),"🟡 تجربة تنتهي خلال "&(W15-TODAY())&" يوم",""))))
A16: 12 | B16: EMP012 | C16: ماجد سلطان الغامدي | D16: سعودي | E16: المبيعات | F16: مدير المبيعات | G16: نشط | H16: 20000 | I16: 5000 | J16: 1500 | K16: =IF(H16<>"",H16+I16+J16,"") -> 26500 | L16: =DATEVALUE("2019-07-01") -> 43647 | M16: =IF(L16<>"",DATEDIF(L16,TODAY(),"Y"),"") -> 6 | N16: 1112345678 | O16: 501230003 | P16: majed.alghamdi@techvision.sa | Q16: =IF(B16="","",AC16-IFERROR(SUMIFS('🌴 الإجازات'!$G:$G,'🌴 الإجازات'!$B:$B,B16,'🌴 الإجازات'!$K:$K,"معتمدة"),0)) -> 30 | R16: فاطمة الزهراني | T16: دائم | U16: =DATEVALUE("2019-07-01") -> 43647 | Y16: 100200300412 | Z16: SA0311112222333344445566 | AA16: بوبا - VIP | AB16: =IF(AND(B16<>"",L16<>""),(0.5*H16*MIN(M16,5))+(1*H16*MAX(0,M16-5)),"") -> 70000 | AC16: =IF(B16<>"",IF(IFERROR(M16,0)>=5,LeaveDaysSenior,LeaveDaysJunior),"") -> 30 | AD16: =IF(B16="","",IF(AND(X16<>"",X16-TODAY()<=ExpiryWarnDays,X16-TODAY()>=0),"⚠️ إقامة تنتهي خلال "&(X16-TODAY())&" يوم",IF(AND(V16<>"",V16-TODAY()<=ExpiryWarnDays,V16-TODAY()>=0),"⚠️ عقد ينتهي خلال "&(V16-TODAY())&" يوم",IF(AND(W16<>"",W16-TODAY()<=30,W16-TODAY()>=0),"🟡 تجربة تنتهي خلال "&(W16-TODAY())&" يوم",""))))
A17: 13 | B17: EMP013 | C17: سارة أحمد الحربي | D17: سعودية | E17: المبيعات | F17: مندوب مبيعات أول | G17: نشط | H17: 10000 | I17: 2500 | J17: 1500 | K17: =IF(H17<>"",H17+I17+J17,"") -> 14000 | L17: =DATEVALUE("2021-09-20") -> 44459 | M17: =IF(L17<>"",DATEDIF(L17,TODAY(),"Y"),"") -> 4 | N17: 2123456789 | O17: 501230004 | P17: sara.alharbi@techvision.sa | Q17: =IF(B17="","",AC17-IFERROR(SUMIFS('🌴 الإجازات'!$G:$G,'🌴 الإجازات'!$B:$B,B17,'🌴 الإجازات'!$K:$K,"معتمدة"),0)) -> 21 | R17: ماجد الغامدي | S17: موظفة الربع الأول 2026 | T17: دائم | U17: =DATEVALUE("2021-09-20") -> 44459 | Y17: 100200300413 | Z17: SA0322223333444455556677 | AA17: بوبا - VIP | AB17: =IF(AND(B17<>"",L17<>""),(0.5*H17*MIN(M17,5))+(1*H17*MAX(0,M17-5)),"") -> 20000 | AC17: =IF(B17<>"",IF(IFERROR(M17,0)>=5,LeaveDaysSenior,LeaveDaysJunior),"") -> 21 | AD17: =IF(B17="","",IF(AND(X17<>"",X17-TODAY()<=ExpiryWarnDays,X17-TODAY()>=0),"⚠️ إقامة تنتهي خلال "&(X17-TODAY())&" يوم",IF(AND(V17<>"",V17-TODAY()<=ExpiryWarnDays,V17-TODAY()>=0),"⚠️ عقد ينتهي خلال "&(V17-TODAY())&" يوم",IF(AND(W17<>"",W17-TODAY()<=30,W17-TODAY()>=0),"🟡 تجربة تنتهي خلال "&(W17-TODAY())&" يوم",""))))
A18: 14 | B18: EMP014 | C18: بدر فهد المطيري | D18: سعودي | E18: المبيعات | F18: مندوب مبيعات | G18: نشط | H18: 8000 | I18: 2000 | J18: 1200 | K18: =IF(H18<>"",H18+I18+J18,"") -> 11200 | L18: =DATEVALUE("2023-03-15") -> 45000 | M18: =IF(L18<>"",DATEDIF(L18,TODAY(),"Y"),"") -> 3 | N18: 1134567890 | O18: 501230005 | P18: badr.almutairi@techvision.sa | Q18: =IF(B18="","",AC18-IFERROR(SUMIFS('🌴 الإجازات'!$G:$G,'🌴 الإجازات'!$B:$B,B18,'🌴 الإجازات'!$K:$K,"معتمدة"),0)) -> 21 | R18: ماجد الغامدي | S18: إنذار غياب متكرر | T18: دائم | U18: =DATEVALUE("2023-03-15") -> 45000 | Y18: 100200300414 | Z18: SA0333334444555566667788 | AA18: بوبا - فضي | AB18: =IF(AND(B18<>"",L18<>""),(0.5*H18*MIN(M18,5))+(1*H18*MAX(0,M18-5)),"") -> 12000 | AC18: =IF(B18<>"",IF(IFERROR(M18,0)>=5,LeaveDaysSenior,LeaveDaysJunior),"") -> 21 | AD18: =IF(B18="","",IF(AND(X18<>"",X18-TODAY()<=ExpiryWarnDays,X18-TODAY()>=0),"⚠️ إقامة تنتهي خلال "&(X18-TODAY())&" يوم",IF(AND(V18<>"",V18-TODAY()<=ExpiryWarnDays,V18-TODAY()>=0),"⚠️ عقد ينتهي خلال "&(V18-TODAY())&" يوم",IF(AND(W18<>"",W18-TODAY()<=30,W18-TODAY()>=0),"🟡 تجربة تنتهي خلال "&(W18-TODAY())&" يوم",""))))
A19: 15 | B19: EMP015 | C19: Omar Khalid Mansour | D19: مصري | E19: المبيعات | F19: مندوب مبيعات | G19: نشط | H19: 7000 | I19: 1750 | J19: 1000 | K19: =IF(H19<>"",H19+I19+J19,"") -> 9750 | L19: =DATEVALUE("2024-04-01") -> 45383 | M19: =IF(L19<>"",DATEDIF(L19,TODAY(),"Y"),"") -> 2 | N19: 2789012345678 | O19: 501230006 | P19: omar.mansour@techvision.sa | Q19: =IF(B19="","",AC19-IFERROR(SUMIFS('🌴 الإجازات'!$G:$G,'🌴 الإجازات'!$B:$B,B19,'🌴 الإجازات'!$K:$K,"معتمدة"),0)) -> 14 | R19: ماجد الغامدي | S19: إقامة وعقد ينتهيان قريباً | T19: محدد المدة | U19: =DATEVALUE("2024-04-01") -> 45383 | V19: =DATEVALUE("2026-06-30") -> 46203 | X19: =DATEVALUE("2026-05-30") -> 46172 | Z19: SA0344445555666677778899 | AA19: ميدغلف - فضي | AB19: =IF(AND(B19<>"",L19<>""),(0.5*H19*MIN(M19,5))+(1*H19*MAX(0,M19-5)),"") -> 7000 | AC19: =IF(B19<>"",IF(IFERROR(M19,0)>=5,LeaveDaysSenior,LeaveDaysJunior),"") -> 21 | AD19: =IF(B19="","",IF(AND(X19<>"",X19-TODAY()<=ExpiryWarnDays,X19-TODAY()>=0),"⚠️ إقامة تنتهي خلال "&(X19-TODAY())&" يوم",IF(AND(V19<>"",V19-TODAY()<=ExpiryWarnDays,V19-TODAY()>=0),"⚠️ عقد ينتهي خلال "&(V19-TODAY())&" يوم",IF(AND(W19<>"",W19-TODAY()<=30,W19-TODAY()>=0),"🟡 تجربة تنتهي خلال "&(W19-TODAY())&" يوم","")))) -> ⚠️ إقامة تنتهي خلال 26 يوم
A20: 16 | B20: EMP016 | C20: هند ناصر القرشي | D20: سعودية | E20: المبيعات | F20: مندوب مبيعات Junior | G20: نشط | H20: 6000 | I20: 1500 | J20: 800 | K20: =IF(H20<>"",H20+I20+J20,"") -> 8300 | L20: =DATEVALUE("2026-01-15") -> 46037 | M20: =IF(L20<>"",DATEDIF(L20,TODAY(),"Y"),"") -> 0 | N20: 2156789012 | O20: 501230007 | P20: hind.alqarashi@techvision.sa | Q20: =IF(B20="","",AC20-IFERROR(SUMIFS('🌴 الإجازات'!$G:$G,'🌴 الإجازات'!$B:$B,B20,'🌴 الإجازات'!$K:$K,"معتمدة"),0)) -> 21 | R20: ماجد الغامدي | S20: فترة تجربة منتهية - بحاجة قرار | T20: تجربة | U20: =DATEVALUE("2026-01-15") -> 46037 | W20: =DATEVALUE("2026-04-15") -> 46127 | Y20: 100200300416 | Z20: SA0355556666777788889911 | AA20: بوبا - فضي | AB20: =IF(AND(B20<>"",L20<>""),(0.5*H20*MIN(M20,5))+(1*H20*MAX(0,M20-5)),"") -> 0 | AC20: =IF(B20<>"",IF(IFERROR(M20,0)>=5,LeaveDaysSenior,LeaveDaysJunior),"") -> 21 | AD20: =IF(B20="","",IF(AND(X20<>"",X20-TODAY()<=ExpiryWarnDays,X20-TODAY()>=0),"⚠️ إقامة تنتهي خلال "&(X20-TODAY())&" يوم",IF(AND(V20<>"",V20-TODAY()<=ExpiryWarnDays,V20-TODAY()>=0),"⚠️ عقد ينتهي خلال "&(V20-TODAY())&" يوم",IF(AND(W20<>"",W20-TODAY()<=30,W20-TODAY()>=0),"🟡 تجربة تنتهي خلال "&(W20-TODAY())&" يوم",""))))
A21: 17 | B21: EMP017 | C21: عبدالملك سعد التميمي | D21: سعودي | E21: التسويق | F21: مدير التسويق | G21: نشط | H21: 18000 | I21: 4500 | J21: 1200 | K21: =IF(H21<>"",H21+I21+J21,"") -> 23700 | L21: =DATEVALUE("2020-05-15") -> 43966 | M21: =IF(L21<>"",DATEDIF(L21,TODAY(),"Y"),"") -> 5 | N21: 1167890123 | O21: 501230008 | P21: abdulmalik.altamimi@techvision.sa | Q21: =IF(B21="","",AC21-IFERROR(SUMIFS('🌴 الإجازات'!$G:$G,'🌴 الإجازات'!$B:$B,B21,'🌴 الإجازات'!$K:$K,"معتمدة"),0)) -> 30 | R21: فاطمة الزهراني | T21: دائم | U21: =DATEVALUE("2020-05-15") -> 43966 | Y21: 100200300417 | Z21: SA0366667777888899990022 | AA21: بوبا - VIP | AB21: =IF(AND(B21<>"",L21<>""),(0.5*H21*MIN(M21,5))+(1*H21*MAX(0,M21-5)),"") -> 45000 | AC21: =IF(B21<>"",IF(IFERROR(M21,0)>=5,LeaveDaysSenior,LeaveDaysJunior),"") -> 30 | AD21: =IF(B21="","",IF(AND(X21<>"",X21-TODAY()<=ExpiryWarnDays,X21-TODAY()>=0),"⚠️ إقامة تنتهي خلال "&(X21-TODAY())&" يوم",IF(AND(V21<>"",V21-TODAY()<=ExpiryWarnDays,V21-TODAY()>=0),"⚠️ عقد ينتهي خلال "&(V21-TODAY())&" يوم",IF(AND(W21<>"",W21-TODAY()<=30,W21-TODAY()>=0),"🟡 تجربة تنتهي خلال "&(W21-TODAY())&" يوم",""))))
A22: 18 | B22: EMP018 | C22: لمى محمد البرقاوي | D22: سعودية | E22: التسويق | F22: أخصائية تسويق رقمي | G22: نشط | H22: 10000 | I22: 2500 | J22: 800 | K22: =IF(H22<>"",H22+I22+J22,"") -> 13300 | L22: =DATEVALUE("2022-02-10") -> 44602 | M22: =IF(L22<>"",DATEDIF(L22,TODAY(),"Y"),"") -> 4 | N22: 2178901234 | O22: 501230009 | P22: lama.albarqawi@techvision.sa | Q22: =IF(B22="","",AC22-IFERROR(SUMIFS('🌴 الإجازات'!$G:$G,'🌴 الإجازات'!$B:$B,B22,'🌴 الإجازات'!$K:$K,"معتمدة"),0)) -> 11 | R22: عبدالملك التميمي | T22: دائم | U22: =DATEVALUE("2022-02-10") -> 44602 | Y22: 100200300418 | Z22: SA0377778888999900001133 | AA22: بوبا - فضي | AB22: =IF(AND(B22<>"",L22<>""),(0.5*H22*MIN(M22,5))+(1*H22*MAX(0,M22-5)),"") -> 20000 | AC22: =IF(B22<>"",IF(IFERROR(M22,0)>=5,LeaveDaysSenior,LeaveDaysJunior),"") -> 21 | AD22: =IF(B22="","",IF(AND(X22<>"",X22-TODAY()<=ExpiryWarnDays,X22-TODAY()>=0),"⚠️ إقامة تنتهي خلال "&(X22-TODAY())&" يوم",IF(AND(V22<>"",V22-TODAY()<=ExpiryWarnDays,V22-TODAY()>=0),"⚠️ عقد ينتهي خلال "&(V22-TODAY())&" يوم",IF(AND(W22<>"",W22-TODAY()<=30,W22-TODAY()>=0),"🟡 تجربة تنتهي خلال "&(W22-TODAY())&" يوم",""))))
A23: 19 | B23: EMP019 | C23: Maria Garcia Lopez | D23: فلبينية | E23: التسويق | F23: مصممة جرافيك | G23: نشط | H23: 8500 | I23: 2125 | J23: 750 | K23: =IF(H23<>"",H23+I23+J23,"") -> 11375 | L23: =DATEVALUE("2023-08-01") -> 45139 | M23: =IF(L23<>"",DATEDIF(L23,TODAY(),"Y"),"") -> 2 | N23: 2890123456789 | O23: 501230010 | P23: maria.lopez@techvision.sa | Q23: =IF(B23="","",AC23-IFERROR(SUMIFS('🌴 الإجازات'!$G:$G,'🌴 الإجازات'!$B:$B,B23,'🌴 الإجازات'!$K:$K,"معتمدة"),0)) -> 12 | R23: عبدالملك التميمي | S23: حالياً في إجازة سنوية | T23: محدد المدة | U23: =DATEVALUE("2023-08-01") -> 45139 | V23: =DATEVALUE("2026-07-31") -> 46234 | X23: =DATEVALUE("2026-09-15") -> 46280 | Z23: SA0388889999000011112233 | AA23: ميدغلف - فضي | AB23: =IF(AND(B23<>"",L23<>""),(0.5*H23*MIN(M23,5))+(1*H23*MAX(0,M23-5)),"") -> 8500 | AC23: =IF(B23<>"",IF(IFERROR(M23,0)>=5,LeaveDaysSenior,LeaveDaysJunior),"") -> 21 | AD23: =IF(B23="","",IF(AND(X23<>"",X23-TODAY()<=ExpiryWarnDays,X23-TODAY()>=0),"⚠️ إقامة تنتهي خلال "&(X23-TODAY())&" يوم",IF(AND(V23<>"",V23-TODAY()<=ExpiryWarnDays,V23-TODAY()>=0),"⚠️ عقد ينتهي خلال "&(V23-TODAY())&" يوم",IF(AND(W23<>"",W23-TODAY()<=30,W23-TODAY()>=0),"🟡 تجربة تنتهي خلال "&(W23-TODAY())&" يوم",""))))
A24: 20 | B24: EMP020 | C24: حنان عبدالكريم الخميس | D24: سعودية | E24: الموارد البشرية | F24: مديرة الموارد البشرية | G24: نشط | H24: 16000 | I24: 4000 | J24: 1100 | K24: =IF(H24<>"",H24+I24+J24,"") -> 21100 | L24: =DATEVALUE("2020-11-01") -> 44136 | M24: =IF(L24<>"",DATEDIF(L24,TODAY(),"Y"),"") -> 5 | N24: 2189012345 | O24: 501230011 | P24: hanan.alkhamis@techvision.sa | Q24: =IF(B24="","",AC24-IFERROR(SUMIFS('🌴 الإجازات'!$G:$G,'🌴 الإجازات'!$B:$B,B24,'🌴 الإجازات'!$K:$K,"معتمدة"),0)) -> 30 | R24: فاطمة الزهراني | T24: دائم | U24: =DATEVALUE("2020-11-01") -> 44136 | Y24: 100200300420 | Z24: SA0399990000111122223344 | AA24: بوبا - VIP | AB24: =IF(AND(B24<>"",L24<>""),(0.5*H24*MIN(M24,5))+(1*H24*MAX(0,M24-5)),"") -> 40000 | AC24: =IF(B24<>"",IF(IFERROR(M24,0)>=5,LeaveDaysSenior,LeaveDaysJunior),"") -> 30 | AD24: =IF(B24="","",IF(AND(X24<>"",X24-TODAY()<=ExpiryWarnDays,X24-TODAY()>=0),"⚠️ إقامة تنتهي خلال "&(X24-TODAY())&" يوم",IF(AND(V24<>"",V24-TODAY()<=ExpiryWarnDays,V24-TODAY()>=0),"⚠️ عقد ينتهي خلال "&(V24-TODAY())&" يوم",IF(AND(W24<>"",W24-TODAY()<=30,W24-TODAY()>=0),"🟡 تجربة تنتهي خلال "&(W24-TODAY())&" يوم",""))))
A25: 21 | B25: EMP021 | C25: ريان محمد العسيري | D25: سعودي | E25: الموارد البشرية | F25: أخصائي موارد بشرية | G25: نشط | H25: 8500 | I25: 2125 | J25: 700 | K25: =IF(H25<>"",H25+I25+J25,"") -> 11325 | L25: =DATEVALUE("2023-06-01") -> 45078 | M25: =IF(L25<>"",DATEDIF(L25,TODAY(),"Y"),"") -> 2 | N25: 1190123456 | O25: 501230012 | P25: rayan.alasiri@techvision.sa | Q25: =IF(B25="","",AC25-IFERROR(SUMIFS('🌴 الإجازات'!$G:$G,'🌴 الإجازات'!$B:$B,B25,'🌴 الإجازات'!$K:$K,"معتمدة"),0)) -> 20 | R25: حنان الخميس | T25: دائم | U25: =DATEVALUE("2023-06-01") -> 45078 | Y25: 100200300421 | Z25: SA0300001111222233334455 | AA25: بوبا - فضي | AB25: =IF(AND(B25<>"",L25<>""),(0.5*H25*MIN(M25,5))+(1*H25*MAX(0,M25-5)),"") -> 8500 | AC25: =IF(B25<>"",IF(IFERROR(M25,0)>=5,LeaveDaysSenior,LeaveDaysJunior),"") -> 21 | AD25: =IF(B25="","",IF(AND(X25<>"",X25-TODAY()<=ExpiryWarnDays,X25-TODAY()>=0),"⚠️ إقامة تنتهي خلال "&(X25-TODAY())&" يوم",IF(AND(V25<>"",V25-TODAY()<=ExpiryWarnDays,V25-TODAY()>=0),"⚠️ عقد ينتهي خلال "&(V25-TODAY())&" يوم",IF(AND(W25<>"",W25-TODAY()<=30,W25-TODAY()>=0),"🟡 تجربة تنتهي خلال "&(W25-TODAY())&" يوم",""))))
A26: 22 | B26: EMP022 | C26: عبدالله صالح الراشد | D26: سعودي | E26: المحاسبة | F26: مدير المحاسبة | G26: نشط | H26: 17000 | I26: 4250 | J26: 1100 | K26: =IF(H26<>"",H26+I26+J26,"") -> 22350 | L26: =DATEVALUE("2019-04-20") -> 43575 | M26: =IF(L26<>"",DATEDIF(L26,TODAY(),"Y"),"") -> 7 | N26: 1201234567 | O26: 501230013 | P26: abdullah.alrashid@techvision.sa | Q26: =IF(B26="","",AC26-IFERROR(SUMIFS('🌴 الإجازات'!$G:$G,'🌴 الإجازات'!$B:$B,B26,'🌴 الإجازات'!$K:$K,"معتمدة"),0)) -> 30 | R26: خالد الدوسري | T26: دائم | U26: =DATEVALUE("2019-04-20") -> 43575 | Y26: 100200300422 | Z26: SA0311112222333344445566 | AA26: بوبا - VIP | AB26: =IF(AND(B26<>"",L26<>""),(0.5*H26*MIN(M26,5))+(1*H26*MAX(0,M26-5)),"") -> 76500 | AC26: =IF(B26<>"",IF(IFERROR(M26,0)>=5,LeaveDaysSenior,LeaveDaysJunior),"") -> 30 | AD26: =IF(B26="","",IF(AND(X26<>"",X26-TODAY()<=ExpiryWarnDays,X26-TODAY()>=0),"⚠️ إقامة تنتهي خلال "&(X26-TODAY())&" يوم",IF(AND(V26<>"",V26-TODAY()<=ExpiryWarnDays,V26-TODAY()>=0),"⚠️ عقد ينتهي خلال "&(V26-TODAY())&" يوم",IF(AND(W26<>"",W26-TODAY()<=30,W26-TODAY()>=0),"🟡 تجربة تنتهي خلال "&(W26-TODAY())&" يوم",""))))
A27: 23 | B27: EMP023 | C27: منى عبدالله الجهني | D27: سعودية | E27: المحاسبة | F27: محاسبة أولى | G27: نشط | H27: 9500 | I27: 2375 | J27: 750 | K27: =IF(H27<>"",H27+I27+J27,"") -> 12625 | L27: =DATEVALUE("2022-05-15") -> 44696 | M27: =IF(L27<>"",DATEDIF(L27,TODAY(),"Y"),"") -> 3 | N27: 2212345678 | O27: 501230014 | P27: muna.aljuhani@techvision.sa | Q27: =IF(B27="","",AC27-IFERROR(SUMIFS('🌴 الإجازات'!$G:$G,'🌴 الإجازات'!$B:$B,B27,'🌴 الإجازات'!$K:$K,"معتمدة"),0)) -> 21 | R27: عبدالله الراشد | T27: دائم | U27: =DATEVALUE("2022-05-15") -> 44696 | Y27: 100200300423 | Z27: SA0322223333444455556677 | AA27: بوبا - فضي | AB27: =IF(AND(B27<>"",L27<>""),(0.5*H27*MIN(M27,5))+(1*H27*MAX(0,M27-5)),"") -> 14250 | AC27: =IF(B27<>"",IF(IFERROR(M27,0)>=5,LeaveDaysSenior,LeaveDaysJunior),"") -> 21 | AD27: =IF(B27="","",IF(AND(X27<>"",X27-TODAY()<=ExpiryWarnDays,X27-TODAY()>=0),"⚠️ إقامة تنتهي خلال "&(X27-TODAY())&" يوم",IF(AND(V27<>"",V27-TODAY()<=ExpiryWarnDays,V27-TODAY()>=0),"⚠️ عقد ينتهي خلال "&(V27-TODAY())&" يوم",IF(AND(W27<>"",W27-TODAY()<=30,W27-TODAY()>=0),"🟡 تجربة تنتهي خلال "&(W27-TODAY())&" يوم",""))))
A28: 24 | B28: EMP024 | C28: Hassan Ali Khoury | D28: لبناني | E28: المحاسبة | F28: محاسب | G28: نشط | H28: 8000 | I28: 2000 | J28: 700 | K28: =IF(H28<>"",H28+I28+J28,"") -> 10700 | L28: =DATEVALUE("2024-07-01") -> 45474 | M28: =IF(L28<>"",DATEDIF(L28,TODAY(),"Y"),"") -> 1 | N28: 2901234567890 | O28: 501230015 | P28: hassan.khoury@techvision.sa | Q28: =IF(B28="","",AC28-IFERROR(SUMIFS('🌴 الإجازات'!$G:$G,'🌴 الإجازات'!$B:$B,B28,'🌴 الإجازات'!$K:$K,"معتمدة"),0)) -> 18 | R28: عبدالله الراشد | T28: محدد المدة | U28: =DATEVALUE("2024-07-01") -> 45474 | V28: =DATEVALUE("2027-06-30") -> 46568 | X28: =DATEVALUE("2027-01-10") -> 46397 | Z28: SA0333334444555566667788 | AA28: ميدغلف - فضي | AB28: =IF(AND(B28<>"",L28<>""),(0.5*H28*MIN(M28,5))+(1*H28*MAX(0,M28-5)),"") -> 4000 | AC28: =IF(B28<>"",IF(IFERROR(M28,0)>=5,LeaveDaysSenior,LeaveDaysJunior),"") -> 21 | AD28: =IF(B28="","",IF(AND(X28<>"",X28-TODAY()<=ExpiryWarnDays,X28-TODAY()>=0),"⚠️ إقامة تنتهي خلال "&(X28-TODAY())&" يوم",IF(AND(V28<>"",V28-TODAY()<=ExpiryWarnDays,V28-TODAY()>=0),"⚠️ عقد ينتهي خلال "&(V28-TODAY())&" يوم",IF(AND(W28<>"",W28-TODAY()<=30,W28-TODAY()>=0),"🟡 تجربة تنتهي خلال "&(W28-TODAY())&" يوم",""))))
A29: 25 | B29: EMP025 | C29: ناصر علي الشمراني | D29: سعودي | E29: خدمة العملاء | F29: مشرف خدمة عملاء | G29: نشط | H29: 11000 | I29: 2750 | J29: 900 | K29: =IF(H29<>"",H29+I29+J29,"") -> 14650 | L29: =DATEVALUE("2021-01-15") -> 44211 | M29: =IF(L29<>"",DATEDIF(L29,TODAY(),"Y"),"") -> 5 | N29: 1223456789 | O29: 501230016 | P29: nasser.alshamrani@techvision.sa | Q29: =IF(B29="","",AC29-IFERROR(SUMIFS('🌴 الإجازات'!$G:$G,'🌴 الإجازات'!$B:$B,B29,'🌴 الإجازات'!$K:$K,"معتمدة"),0)) -> 30 | R29: فاطمة الزهراني | T29: دائم | U29: =DATEVALUE("2021-01-15") -> 44211 | Y29: 100200300425 | Z29: SA0344445555666677778899 | AA29: بوبا - VIP | AB29: =IF(AND(B29<>"",L29<>""),(0.5*H29*MIN(M29,5))+(1*H29*MAX(0,M29-5)),"") -> 27500 | AC29: =IF(B29<>"",IF(IFERROR(M29,0)>=5,LeaveDaysSenior,LeaveDaysJunior),"") -> 30 | AD29: =IF(B29="","",IF(AND(X29<>"",X29-TODAY()<=ExpiryWarnDays,X29-TODAY()>=0),"⚠️ إقامة تنتهي خلال "&(X29-TODAY())&" يوم",IF(AND(V29<>"",V29-TODAY()<=ExpiryWarnDays,V29-TODAY()>=0),"⚠️ عقد ينتهي خلال "&(V29-TODAY())&" يوم",IF(AND(W29<>"",W29-TODAY()<=30,W29-TODAY()>=0),"🟡 تجربة تنتهي خلال "&(W29-TODAY())&" يوم",""))))
A30: 26 | B30: EMP026 | C30: عبير ماجد الصاعدي | D30: سعودية | E30: خدمة العملاء | F30: موظفة خدمة عملاء | G30: موقوف | H30: 6500 | I30: 1625 | J30: 500 | K30: =IF(H30<>"",H30+I30+J30,"") -> 8625 | L30: =DATEVALUE("2023-09-01") -> 45170 | M30: =IF(L30<>"",DATEDIF(L30,TODAY(),"Y"),"") -> 2 | N30: 2234567890 | O30: 501230017 | P30: abeer.alsaedi@techvision.sa | Q30: =IF(B30="","",AC30-IFERROR(SUMIFS('🌴 الإجازات'!$G:$G,'🌴 الإجازات'!$B:$B,B30,'🌴 الإجازات'!$K:$K,"معتمدة"),0)) -> 21 | R30: ناصر الشمراني | S30: موقوفة عن العمل من 2026-04-15 لتحقيق إداري | T30: دائم | U30: =DATEVALUE("2023-09-01") -> 45170 | Y30: 100200300426 | Z30: SA0355556666777788889911 | AA30: بوبا - فضي | AB30: =IF(AND(B30<>"",L30<>""),(0.5*H30*MIN(M30,5))+(1*H30*MAX(0,M30-5)),"") -> 6500 | AC30: =IF(B30<>"",IF(IFERROR(M30,0)>=5,LeaveDaysSenior,LeaveDaysJunior),"") -> 21 | AD30: =IF(B30="","",IF(AND(X30<>"",X30-TODAY()<=ExpiryWarnDays,X30-TODAY()>=0),"⚠️ إقامة تنتهي خلال "&(X30-TODAY())&" يوم",IF(AND(V30<>"",V30-TODAY()<=ExpiryWarnDays,V30-TODAY()>=0),"⚠️ عقد ينتهي خلال "&(V30-TODAY())&" يوم",IF(AND(W30<>"",W30-TODAY()<=30,W30-TODAY()>=0),"🟡 تجربة تنتهي خلال "&(W30-TODAY())&" يوم",""))))
A31: 27 | B31: EMP027 | C31: Anwar Singh Rana | D31: هندي | E31: خدمة العملاء | F31: موظف خدمة عملاء | G31: نشط | H31: 5500 | I31: 1375 | J31: 500 | K31: =IF(H31<>"",H31+I31+J31,"") -> 7375 | L31: =DATEVALUE("2024-10-01") -> 45566 | M31: =IF(L31<>"",DATEDIF(L31,TODAY(),"Y"),"") -> 1 | N31: 2912345678901 | O31: 501230018 | P31: anwar.rana@techvision.sa | Q31: =IF(B31="","",AC31-IFERROR(SUMIFS('🌴 الإجازات'!$G:$G,'🌴 الإجازات'!$B:$B,B31,'🌴 الإجازات'!$K:$K,"معتمدة"),0)) -> 21 | R31: ناصر الشمراني | T31: محدد المدة | U31: =DATEVALUE("2024-10-01") -> 45566 | V31: =DATEVALUE("2026-09-30") -> 46295 | X31: =DATEVALUE("2026-07-20") -> 46223 | Z31: SA0366667777888899990022 | AA31: ميدغلف - فضي | AB31: =IF(AND(B31<>"",L31<>""),(0.5*H31*MIN(M31,5))+(1*H31*MAX(0,M31-5)),"") -> 2750 | AC31: =IF(B31<>"",IF(IFERROR(M31,0)>=5,LeaveDaysSenior,LeaveDaysJunior),"") -> 21 | AD31: =IF(B31="","",IF(AND(X31<>"",X31-TODAY()<=ExpiryWarnDays,X31-TODAY()>=0),"⚠️ إقامة تنتهي خلال "&(X31-TODAY())&" يوم",IF(AND(V31<>"",V31-TODAY()<=ExpiryWarnDays,V31-TODAY()>=0),"⚠️ عقد ينتهي خلال "&(V31-TODAY())&" يوم",IF(AND(W31<>"",W31-TODAY()<=30,W31-TODAY()>=0),"🟡 تجربة تنتهي خلال "&(W31-TODAY())&" يوم",""))))
A32: 28 | B32: EMP028 | C32: Sara Mahmoud Ibrahim | D32: مصرية | E32: خدمة العملاء | F32: موظفة خدمة عملاء | G32: نشط | H32: 5500 | I32: 1375 | J32: 500 | K32: =IF(H32<>"",H32+I32+J32,"") -> 7375 | L32: =DATEVALUE("2025-08-15") -> 45884 | M32: =IF(L32<>"",DATEDIF(L32,TODAY(),"Y"),"") -> 0 | N32: 2923456789012 | O32: 501230019 | P32: sara.ibrahim@techvision.sa | Q32: =IF(B32="","",AC32-IFERROR(SUMIFS('🌴 الإجازات'!$G:$G,'🌴 الإجازات'!$B:$B,B32,'🌴 الإجازات'!$K:$K,"معتمدة"),0)) -> 18 | R32: ناصر الشمراني | T32: دائم | U32: =DATEVALUE("2025-08-15") -> 45884 | X32: =DATEVALUE("2027-02-10") -> 46428 | Z32: SA0377778888999900001133 | AA32: ميدغلف - فضي | AB32: =IF(AND(B32<>"",L32<>""),(0.5*H32*MIN(M32,5))+(1*H32*MAX(0,M32-5)),"") -> 0 | AC32: =IF(B32<>"",IF(IFERROR(M32,0)>=5,LeaveDaysSenior,LeaveDaysJunior),"") -> 21 | AD32: =IF(B32="","",IF(AND(X32<>"",X32-TODAY()<=ExpiryWarnDays,X32-TODAY()>=0),"⚠️ إقامة تنتهي خلال "&(X32-TODAY())&" يوم",IF(AND(V32<>"",V32-TODAY()<=ExpiryWarnDays,V32-TODAY()>=0),"⚠️ عقد ينتهي خلال "&(V32-TODAY())&" يوم",IF(AND(W32<>"",W32-TODAY()<=30,W32-TODAY()>=0),"🟡 تجربة تنتهي خلال "&(W32-TODAY())&" يوم",""))))
A33: 29 | B33: EMP029 | C33: بندر مساعد الشهري | D33: سعودي | E33: العمليات | F33: مدير العمليات | G33: نشط | H33: 15000 | I33: 3750 | J33: 1000 | K33: =IF(H33<>"",H33+I33+J33,"") -> 19750 | L33: =DATEVALUE("2020-08-15") -> 44058 | M33: =IF(L33<>"",DATEDIF(L33,TODAY(),"Y"),"") -> 5 | N33: 1245678901 | O33: 501230020 | P33: bandar.alshehri@techvision.sa | Q33: =IF(B33="","",AC33-IFERROR(SUMIFS('🌴 الإجازات'!$G:$G,'🌴 الإجازات'!$B:$B,B33,'🌴 الإجازات'!$K:$K,"معتمدة"),0)) -> 30 | R33: فاطمة الزهراني | T33: دائم | U33: =DATEVALUE("2020-08-15") -> 44058 | Y33: 100200300429 | Z33: SA0388889999000011112233 | AA33: بوبا - VIP | AB33: =IF(AND(B33<>"",L33<>""),(0.5*H33*MIN(M33,5))+(1*H33*MAX(0,M33-5)),"") -> 37500 | AC33: =IF(B33<>"",IF(IFERROR(M33,0)>=5,LeaveDaysSenior,LeaveDaysJunior),"") -> 30 | AD33: =IF(B33="","",IF(AND(X33<>"",X33-TODAY()<=ExpiryWarnDays,X33-TODAY()>=0),"⚠️ إقامة تنتهي خلال "&(X33-TODAY())&" يوم",IF(AND(V33<>"",V33-TODAY()<=ExpiryWarnDays,V33-TODAY()>=0),"⚠️ عقد ينتهي خلال "&(V33-TODAY())&" يوم",IF(AND(W33<>"",W33-TODAY()<=30,W33-TODAY()>=0),"🟡 تجربة تنتهي خلال "&(W33-TODAY())&" يوم",""))))
A34: 30 | B34: EMP030 | C34: ياسر سالم الزهراني | D34: سعودي | E34: العمليات | F34: محلل عمليات | G34: منتهي الخدمة | H34: 8500 | I34: 2125 | J34: 700 | K34: =IF(H34<>"",H34+I34+J34,"") -> 11325 | L34: =DATEVALUE("2022-03-01") -> 44621 | M34: =IF(L34<>"",DATEDIF(L34,TODAY(),"Y"),"") -> 4 | N34: 1256789012 | O34: 501230021 | P34: yasser.alzahrani@techvision.sa | Q34: =IF(B34="","",AC34-IFERROR(SUMIFS('🌴 الإجازات'!$G:$G,'🌴 الإجازات'!$B:$B,B34,'🌴 الإجازات'!$K:$K,"معتمدة"),0)) -> 21 | R34: بندر الشهري | S34: انتهت الخدمة في 2026-04-15 - استقالة | T34: دائم | U34: =DATEVALUE("2022-03-01") -> 44621 | V34: =DATEVALUE("2026-04-15") -> 46127 | Y34: 100200300430 | Z34: SA0399990000111122223344 | AA34: بوبا - فضي | AB34: =IF(AND(B34<>"",L34<>""),(0.5*H34*MIN(M34,5))+(1*H34*MAX(0,M34-5)),"") -> 17000 | AC34: =IF(B34<>"",IF(IFERROR(M34,0)>=5,LeaveDaysSenior,LeaveDaysJunior),"") -> 21 | AD34: =IF(B34="","",IF(AND(X34<>"",X34-TODAY()<=ExpiryWarnDays,X34-TODAY()>=0),"⚠️ إقامة تنتهي خلال "&(X34-TODAY())&" يوم",IF(AND(V34<>"",V34-TODAY()<=ExpiryWarnDays,V34-TODAY()>=0),"⚠️ عقد ينتهي خلال "&(V34-TODAY())&" يوم",IF(AND(W34<>"",W34-TODAY()<=30,W34-TODAY()>=0),"🟡 تجربة تنتهي خلال "&(W34-TODAY())&" يوم",""))))
K35: =IF(H35<>"",H35+I35+J35,"") | M35: =IF(L35<>"",DATEDIF(L35,TODAY(),"Y"),"") | Q35: =IF(B35="","",AC35-IFERROR(SUMIFS('🌴 الإجازات'!$G:$G,'🌴 الإجازات'!$B:$B,B35,'🌴 الإجازات'!$K:$K,"معتمدة"),0)) | AB35: =IF(AND(B35<>"",L35<>""),(0.5*H35*MIN(M35,5))+(1*H35*MAX(0,M35-5)),"") | AC35: =IF(B35<>"",IF(IFERROR(M35,0)>=5,LeaveDaysSenior,LeaveDaysJunior),"") | AD35: =IF(B35="","",IF(AND(X35<>"",X35-TODAY()<=ExpiryWarnDays,X35-TODAY()>=0),"⚠️ إقامة تنتهي خلال "&(X35-TODAY())&" يوم",IF(AND(V35<>"",V35-TODAY()<=ExpiryWarnDays,V35-TODAY()>=0),"⚠️ عقد ينتهي خلال "&(V35-TODAY())&" يوم",IF(AND(W35<>"",W35-TODAY()<=30,W35-TODAY()>=0),"🟡 تجربة تنتهي خلال "&(W35-TODAY())&" يوم",""))))
K36: =IF(H36<>"",H36+I36+J36,"") | M36: =IF(L36<>"",DATEDIF(L36,TODAY(),"Y"),"") | Q36: =IF(B36="","",AC36-IFERROR(SUMIFS('🌴 الإجازات'!$G:$G,'🌴 الإجازات'!$B:$B,B36,'🌴 الإجازات'!$K:$K,"معتمدة"),0)) | AB36: =IF(AND(B36<>"",L36<>""),(0.5*H36*MIN(M36,5))+(1*H36*MAX(0,M36-5)),"") | AC36: =IF(B36<>"",IF(IFERROR(M36,0)>=5,LeaveDaysSenior,LeaveDaysJunior),"") | AD36: =IF(B36="","",IF(AND(X36<>"",X36-TODAY()<=ExpiryWarnDays,X36-TODAY()>=0),"⚠️ إقامة تنتهي خلال "&(X36-TODAY())&" يوم",IF(AND(V36<>"",V36-TODAY()<=ExpiryWarnDays,V36-TODAY()>=0),"⚠️ عقد ينتهي خلال "&(V36-TODAY())&" يوم",IF(AND(W36<>"",W36-TODAY()<=30,W36-TODAY()>=0),"🟡 تجربة تنتهي خلال "&(W36-TODAY())&" يوم",""))))
K37: =IF(H37<>"",H37+I37+J37,"") | M37: =IF(L37<>"",DATEDIF(L37,TODAY(),"Y"),"") | Q37: =IF(B37="","",AC37-IFERROR(SUMIFS('🌴 الإجازات'!$G:$G,'🌴 الإجازات'!$B:$B,B37,'🌴 الإجازات'!$K:$K,"معتمدة"),0)) | AB37: =IF(AND(B37<>"",L37<>""),(0.5*H37*MIN(M37,5))+(1*H37*MAX(0,M37-5)),"") | AC37: =IF(B37<>"",IF(IFERROR(M37,0)>=5,LeaveDaysSenior,LeaveDaysJunior),"") | AD37: =IF(B37="","",IF(AND(X37<>"",X37-TODAY()<=ExpiryWarnDays,X37-TODAY()>=0),"⚠️ إقامة تنتهي خلال "&(X37-TODAY())&" يوم",IF(AND(V37<>"",V37-TODAY()<=ExpiryWarnDays,V37-TODAY()>=0),"⚠️ عقد ينتهي خلال "&(V37-TODAY())&" يوم",IF(AND(W37<>"",W37-TODAY()<=30,W37-TODAY()>=0),"🟡 تجربة تنتهي خلال "&(W37-TODAY())&" يوم",""))))
K38: =IF(H38<>"",H38+I38+J38,"") | M38: =IF(L38<>"",DATEDIF(L38,TODAY(),"Y"),"") | Q38: =IF(B38="","",AC38-IFERROR(SUMIFS('🌴 الإجازات'!$G:$G,'🌴 الإجازات'!$B:$B,B38,'🌴 الإجازات'!$K:$K,"معتمدة"),0)) | AB38: =IF(AND(B38<>"",L38<>""),(0.5*H38*MIN(M38,5))+(1*H38*MAX(0,M38-5)),"") | AC38: =IF(B38<>"",IF(IFERROR(M38,0)>=5,LeaveDaysSenior,LeaveDaysJunior),"") | AD38: =IF(B38="","",IF(AND(X38<>"",X38-TODAY()<=ExpiryWarnDays,X38-TODAY()>=0),"⚠️ إقامة تنتهي خلال "&(X38-TODAY())&" يوم",IF(AND(V38<>"",V38-TODAY()<=ExpiryWarnDays,V38-TODAY()>=0),"⚠️ عقد ينتهي خلال "&(V38-TODAY())&" يوم",IF(AND(W38<>"",W38-TODAY()<=30,W38-TODAY()>=0),"🟡 تجربة تنتهي خلال "&(W38-TODAY())&" يوم",""))))
K39: =IF(H39<>"",H39+I39+J39,"") | M39: =IF(L39<>"",DATEDIF(L39,TODAY(),"Y"),"") | Q39: =IF(B39="","",AC39-IFERROR(SUMIFS('🌴 الإجازات'!$G:$G,'🌴 الإجازات'!$B:$B,B39,'🌴 الإجازات'!$K:$K,"معتمدة"),0)) | AB39: =IF(AND(B39<>"",L39<>""),(0.5*H39*MIN(M39,5))+(1*H39*MAX(0,M39-5)),"") | AC39: =IF(B39<>"",IF(IFERROR(M39,0)>=5,LeaveDaysSenior,LeaveDaysJunior),"") | AD39: =IF(B39="","",IF(AND(X39<>"",X39-TODAY()<=ExpiryWarnDays,X39-TODAY()>=0),"⚠️ إقامة تنتهي خلال "&(X39-TODAY())&" يوم",IF(AND(V39<>"",V39-TODAY()<=ExpiryWarnDays,V39-TODAY()>=0),"⚠️ عقد ينتهي خلال "&(V39-TODAY())&" يوم",IF(AND(W39<>"",W39-TODAY()<=30,W39-TODAY()>=0),"🟡 تجربة تنتهي خلال "&(W39-TODAY())&" يوم",""))))
K40: =IF(H40<>"",H40+I40+J40,"") | M40: =IF(L40<>"",DATEDIF(L40,TODAY(),"Y"),"") | Q40: =IF(B40="","",AC40-IFERROR(SUMIFS('🌴 الإجازات'!$G:$G,'🌴 الإجازات'!$B:$B,B40,'🌴 الإجازات'!$K:$K,"معتمدة"),0)) | AB40: =IF(AND(B40<>"",L40<>""),(0.5*H40*MIN(M40,5))+(1*H40*MAX(0,M40-5)),"") | AC40: =IF(B40<>"",IF(IFERROR(M40,0)>=5,LeaveDaysSenior,LeaveDaysJunior),"") | AD40: =IF(B40="","",IF(AND(X40<>"",X40-TODAY()<=ExpiryWarnDays,X40-TODAY()>=0),"⚠️ إقامة تنتهي خلال "&(X40-TODAY())&" يوم",IF(AND(V40<>"",V40-TODAY()<=ExpiryWarnDays,V40-TODAY()>=0),"⚠️ عقد ينتهي خلال "&(V40-TODAY())&" يوم",IF(AND(W40<>"",W40-TODAY()<=30,W40-TODAY()>=0),"🟡 تجربة تنتهي خلال "&(W40-TODAY())&" يوم",""))))
K41: =IF(H41<>"",H41+I41+J41,"") | M41: =IF(L41<>"",DATEDIF(L41,TODAY(),"Y"),"") | Q41: =IF(B41="","",AC41-IFERROR(SUMIFS('🌴 الإجازات'!$G:$G,'🌴 الإجازات'!$B:$B,B41,'🌴 الإجازات'!$K:$K,"معتمدة"),0)) | AB41: =IF(AND(B41<>"",L41<>""),(0.5*H41*MIN(M41,5))+(1*H41*MAX(0,M41-5)),"") | AC41: =IF(B41<>"",IF(IFERROR(M41,0)>=5,LeaveDaysSenior,LeaveDaysJunior),"") | AD41: =IF(B41="","",IF(AND(X41<>"",X41-TODAY()<=ExpiryWarnDays,X41-TODAY()>=0),"⚠️ إقامة تنتهي خلال "&(X41-TODAY())&" يوم",IF(AND(V41<>"",V41-TODAY()<=ExpiryWarnDays,V41-TODAY()>=0),"⚠️ عقد ينتهي خلال "&(V41-TODAY())&" يوم",IF(AND(W41<>"",W41-TODAY()<=30,W41-TODAY()>=0),"🟡 تجربة تنتهي خلال "&(W41-TODAY())&" يوم",""))))
...

Sheet 📅 الحضور
A1: 📅 سجل الحضور والانصراف
A2: Attendance Register — مرتبط تلقائياً بقاعدة بيانات الموظفين
A3: الشهر: | D3: 5 | G3: السنة: | J3: 2026
A4: م | B4: رقم الموظف | C4: اسم الموظف | D4: التاريخ | E4: الحالة | F4: وقت الدخول | G4: وقت الخروج | H4: ساعات العمل | I4: التأخير (دقائق) | J4: ساعات إضافية | K4: ملاحظات | L4: شهر-سنة
A5: 1 | B5: EMP001 | C5: =IFERROR(VLOOKUP(B5,'👥 بيانات الموظفين'!B:C,2,0),"") -> عبدالعزيز محمد العتيبي | D5: =DATEVALUE("2026-04-12") -> 46124 | E5: حاضر | F5: =TIMEVALUE("07:61") -> 0.33402778 | G5: =TIMEVALUE("17:13") -> 0.71736111 | H5: =IFERROR(IF(AND(F5<>"",G5<>""),(G5-F5)*24,""),"") -> 9.2 | I5: =IFERROR(IF(E5="متأخر",MAX(0,(F5-TIME(8,0,0))*1440),0),0) -> 0 | J5: =IFERROR(IF(AND(ISNUMBER(H5),H5>WorkHoursDay),H5-WorkHoursDay,0),0) -> 1.2 | L5: =IF(D5<>"",TEXT(D5,"yyyy-mm"),"") -> 2026-04
A6: 2 | B6: EMP001 | C6: =IFERROR(VLOOKUP(B6,'👥 بيانات الموظفين'!B:C,2,0),"") -> عبدالعزيز محمد العتيبي | D6: =DATEVALUE("2026-04-13") -> 46125 | E6: حاضر | F6: =TIMEVALUE("08:06") -> 0.3375 | G6: =TIMEVALUE("17:12") -> 0.71666667 | H6: =IFERROR(IF(AND(F6<>"",G6<>""),(G6-F6)*24,""),"") -> 9.1 | I6: =IFERROR(IF(E6="متأخر",MAX(0,(F6-TIME(8,0,0))*1440),0),0) -> 0 | J6: =IFERROR(IF(AND(ISNUMBER(H6),H6>WorkHoursDay),H6-WorkHoursDay,0),0) -> 1.1 | L6: =IF(D6<>"",TEXT(D6,"yyyy-mm"),"") -> 2026-04
A7: 3 | B7: EMP001 | C7: =IFERROR(VLOOKUP(B7,'👥 بيانات الموظفين'!B:C,2,0),"") -> عبدالعزيز محمد العتيبي | D7: =DATEVALUE("2026-04-14") -> 46126 | E7: حاضر | F7: =TIMEVALUE("08:06") -> 0.3375 | G7: =TIMEVALUE("17:16") -> 0.71944444 | H7: =IFERROR(IF(AND(F7<>"",G7<>""),(G7-F7)*24,""),"") -> 9.1666667 | I7: =IFERROR(IF(E7="متأخر",MAX(0,(F7-TIME(8,0,0))*1440),0),0) -> 0 | J7: =IFERROR(IF(AND(ISNUMBER(H7),H7>WorkHoursDay),H7-WorkHoursDay,0),0) -> 1.1666667 | L7: =IF(D7<>"",TEXT(D7,"yyyy-mm"),"") -> 2026-04
A8: 4 | B8: EMP001 | C8: =IFERROR(VLOOKUP(B8,'👥 بيانات الموظفين'!B:C,2,0),"") -> عبدالعزيز محمد العتيبي | D8: =DATEVALUE("2026-04-15") -> 46127 | E8: حاضر | F8: =TIMEVALUE("08:02") -> 0.33472222 | G8: =TIMEVALUE("17:13") -> 0.71736111 | H8: =IFERROR(IF(AND(F8<>"",G8<>""),(G8-F8)*24,""),"") -> 9.1833333 | I8: =IFERROR(IF(E8="متأخر",MAX(0,(F8-TIME(8,0,0))*1440),0),0) -> 0 | J8: =IFERROR(IF(AND(ISNUMBER(H8),H8>WorkHoursDay),H8-WorkHoursDay,0),0) -> 1.1833333 | L8: =IF(D8<>"",TEXT(D8,"yyyy-mm"),"") -> 2026-04
A9: 5 | B9: EMP001 | C9: =IFERROR(VLOOKUP(B9,'👥 بيانات الموظفين'!B:C,2,0),"") -> عبدالعزيز محمد العتيبي | D9: =DATEVALUE("2026-04-16") -> 46128 | E9: متأخر | F9: =TIMEVALUE("08:16") -> 0.34444444 | G9: =TIMEVALUE("17:00") -> 0.70833333 | H9: =IFERROR(IF(AND(F9<>"",G9<>""),(G9-F9)*24,""),"") -> 8.7333333 | I9: =IFERROR(IF(E9="متأخر",MAX(0,(F9-TIME(8,0,0))*1440),0),0) -> 16 | J9: =IFERROR(IF(AND(ISNUMBER(H9),H9>WorkHoursDay),H9-WorkHoursDay,0),0) -> 0.73333333 | K9: غياب بدون إذن | L9: =IF(D9<>"",TEXT(D9,"yyyy-mm"),"") -> 2026-04
A10: 6 | B10: EMP001 | C10: =IFERROR(VLOOKUP(B10,'👥 بيانات الموظفين'!B:C,2,0),"") -> عبدالعزيز محمد العتيبي | D10: =DATEVALUE("2026-04-19") -> 46131 | E10: حاضر | F10: =TIMEVALUE("08:06") -> 0.3375 | G10: =TIMEVALUE("17:18") -> 0.72083333 | H10: =IFERROR(IF(AND(F10<>"",G10<>""),(G10-F10)*24,""),"") -> 9.2 | I10: =IFERROR(IF(E10="متأخر",MAX(0,(F10-TIME(8,0,0))*1440),0),0) -> 0 | J10: =IFERROR(IF(AND(ISNUMBER(H10),H10>WorkHoursDay),H10-WorkHoursDay,0),0) -> 1.2 | L10: =IF(D10<>"",TEXT(D10,"yyyy-mm"),"") -> 2026-04
A11: 7 | B11: EMP001 | C11: =IFERROR(VLOOKUP(B11,'👥 بيانات الموظفين'!B:C,2,0),"") -> عبدالعزيز محمد العتيبي | D11: =DATEVALUE("2026-04-20") -> 46132 | E11: حاضر | F11: =TIMEVALUE("08:02") -> 0.33472222 | G11: =TIMEVALUE("17:19") -> 0.72152778 | H11: =IFERROR(IF(AND(F11<>"",G11<>""),(G11-F11)*24,""),"") -> 9.2833333 | I11: =IFERROR(IF(E11="متأخر",MAX(0,(F11-TIME(8,0,0))*1440),0),0) -> 0 | J11: =IFERROR(IF(AND(ISNUMBER(H11),H11>WorkHoursDay),H11-WorkHoursDay,0),0) -> 1.2833333 | L11: =IF(D11<>"",TEXT(D11,"yyyy-mm"),"") -> 2026-04
A12: 8 | B12: EMP001 | C12: =IFERROR(VLOOKUP(B12,'👥 بيانات الموظفين'!B:C,2,0),"") -> عبدالعزيز محمد العتيبي | D12: =DATEVALUE("2026-04-21") -> 46133 | E12: حاضر | F12: =TIMEVALUE("08:06") -> 0.3375 | G12: =TIMEVALUE("17:15") -> 0.71875 | H12: =IFERROR(IF(AND(F12<>"",G12<>""),(G12-F12)*24,""),"") -> 9.15 | I12: =IFERROR(IF(E12="متأخر",MAX(0,(F12-TIME(8,0,0))*1440),0),0) -> 0 | J12: =IFERROR(IF(AND(ISNUMBER(H12),H12>WorkHoursDay),H12-WorkHoursDay,0),0) -> 1.15 | L12: =IF(D12<>"",TEXT(D12,"yyyy-mm"),"") -> 2026-04
A13: 9 | B13: EMP001 | C13: =IFERROR(VLOOKUP(B13,'👥 بيانات الموظفين'!B:C,2,0),"") -> عبدالعزيز محمد العتيبي | D13: =DATEVALUE("2026-04-22") -> 46134 | E13: حاضر | F13: =TIMEVALUE("08:00") -> 0.33333333 | G13: =TIMEVALUE("17:04") -> 0.71111111 | H13: =IFERROR(IF(AND(F13<>"",G13<>""),(G13-F13)*24,""),"") -> 9.0666667 | I13: =IFERROR(IF(E13="متأخر",MAX(0,(F13-TIME(8,0,0))*1440),0),0) -> 0 | J13: =IFERROR(IF(AND(ISNUMBER(H13),H13>WorkHoursDay),H13-WorkHoursDay,0),0) -> 1.0666667 | L13: =IF(D13<>"",TEXT(D13,"yyyy-mm"),"") -> 2026-04
A14: 10 | B14: EMP001 | C14: =IFERROR(VLOOKUP(B14,'👥 بيانات الموظفين'!B:C,2,0),"") -> عبدالعزيز محمد العتيبي | D14: =DATEVALUE("2026-04-23") -> 46135 | E14: حاضر | F14: =TIMEVALUE("08:04") -> 0.33611111 | G14: =TIMEVALUE("17:03") -> 0.71041667 | H14: =IFERROR(IF(AND(F14<>"",G14<>""),(G14-F14)*24,""),"") -> 8.9833333 | I14: =IFERROR(IF(E14="متأخر",MAX(0,(F14-TIME(8,0,0))*1440),0),0) -> 0 | J14: =IFERROR(IF(AND(ISNUMBER(H14),H14>WorkHoursDay),H14-WorkHoursDay,0),0) -> 0.98333333 | L14: =IF(D14<>"",TEXT(D14,"yyyy-mm"),"") -> 2026-04
A15: 11 | B15: EMP001 | C15: =IFERROR(VLOOKUP(B15,'👥 بيانات الموظفين'!B:C,2,0),"") -> عبدالعزيز محمد العتيبي | D15: =DATEVALUE("2026-04-26") -> 46138 | E15: حاضر | F15: =TIMEVALUE("08:04") -> 0.33611111 | G15: =TIMEVALUE("17:15") -> 0.71875 | H15: =IFERROR(IF(AND(F15<>"",G15<>""),(G15-F15)*24,""),"") -> 9.1833333 | I15: =IFERROR(IF(E15="متأخر",MAX(0,(F15-TIME(8,0,0))*1440),0),0) -> 0 | J15: =IFERROR(IF(AND(ISNUMBER(H15),H15>WorkHoursDay),H15-WorkHoursDay,0),0) -> 1.1833333 | L15: =IF(D15<>"",TEXT(D15,"yyyy-mm"),"") -> 2026-04
A16: 12 | B16: EMP001 | C16: =IFERROR(VLOOKUP(B16,'👥 بيانات الموظفين'!B:C,2,0),"") -> عبدالعزيز محمد العتيبي | D16: =DATEVALUE("2026-04-27") -> 46139 | E16: حاضر | F16: =TIMEVALUE("07:58") -> 0.33194444 | G16: =TIMEVALUE("17:08") -> 0.71388889 | H16: =IFERROR(IF(AND(F16<>"",G16<>""),(G16-F16)*24,""),"") -> 9.1666667 | I16: =IFERROR(IF(E16="متأخر",MAX(0,(F16-TIME(8,0,0))*1440),0),0) -> 0 | J16: =IFERROR(IF(AND(ISNUMBER(H16),H16>WorkHoursDay),H16-WorkHoursDay,0),0) -> 1.1666667 | L16: =IF(D16<>"",TEXT(D16,"yyyy-mm"),"") -> 2026-04
A17: 13 | B17: EMP001 | C17: =IFERROR(VLOOKUP(B17,'👥 بيانات الموظفين'!B:C,2,0),"") -> عبدالعزيز محمد العتيبي | D17: =DATEVALUE("2026-04-28") -> 46140 | E17: حاضر | F17: =TIMEVALUE("07:56") -> 0.33055556 | G17: =TIMEVALUE("17:14") -> 0.71805556 | H17: =IFERROR(IF(AND(F17<>"",G17<>""),(G17-F17)*24,""),"") -> 9.3 | I17: =IFERROR(IF(E17="متأخر",MAX(0,(F17-TIME(8,0,0))*1440),0),0) -> 0 | J17: =IFERROR(IF(AND(ISNUMBER(H17),H17>WorkHoursDay),H17-WorkHoursDay,0),0) -> 1.3 | L17: =IF(D17<>"",TEXT(D17,"yyyy-mm"),"") -> 2026-04
A18: 14 | B18: EMP001 | C18: =IFERROR(VLOOKUP(B18,'👥 بيانات الموظفين'!B:C,2,0),"") -> عبدالعزيز محمد العتيبي | D18: =DATEVALUE("2026-04-29") -> 46141 | E18: متأخر | F18: =TIMEVALUE("08:18") -> 0.34583333 | G18: =TIMEVALUE("17:00") -> 0.70833333 | H18: =IFERROR(IF(AND(F18<>"",G18<>""),(G18-F18)*24,""),"") -> 8.7 | I18: =IFERROR(IF(E18="متأخر",MAX(0,(F18-TIME(8,0,0))*1440),0),0) -> 18 | J18: =IFERROR(IF(AND(ISNUMBER(H18),H18>WorkHoursDay),H18-WorkHoursDay,0),0) -> 0.7 | L18: =IF(D18<>"",TEXT(D18,"yyyy-mm"),"") -> 2026-04
A19: 15 | B19: EMP001 | C19: =IFERROR(VLOOKUP(B19,'👥 بيانات الموظفين'!B:C,2,0),"") -> عبدالعزيز محمد العتيبي | D19: =DATEVALUE("2026-04-30") -> 46142 | E19: حاضر | F19: =TIMEVALUE("07:61") -> 0.33402778 | G19: =TIMEVALUE("17:11") -> 0.71597222 | H19: =IFERROR(IF(AND(F19<>"",G19<>""),(G19-F19)*24,""),"") -> 9.1666667 | I19: =IFERROR(IF(E19="متأخر",MAX(0,(F19-TIME(8,0,0))*1440),0),0) -> 0 | J19: =IFERROR(IF(AND(ISNUMBER(H19),H19>WorkHoursDay),H19-WorkHoursDay,0),0) -> 1.1666667 | L19: =IF(D19<>"",TEXT(D19,"yyyy-mm"),"") -> 2026-04
A20: 16 | B20: EMP002 | C20: =IFERROR(VLOOKUP(B20,'👥 بيانات الموظفين'!B:C,2,0),"") -> فاطمة سعد الزهراني | D20: =DATEVALUE("2026-04-12") -> 46124 | E20: حاضر | F20: =TIMEVALUE("08:02") -> 0.33472222 | G20: =TIMEVALUE("17:18") -> 0.72083333 | H20: =IFERROR(IF(AND(F20<>"",G20<>""),(G20-F20)*24,""),"") -> 9.2666667 | I20: =IFERROR(IF(E20="متأخر",MAX(0,(F20-TIME(8,0,0))*1440),0),0) -> 0 | J20: =IFERROR(IF(AND(ISNUMBER(H20),H20>WorkHoursDay),H20-WorkHoursDay,0),0) -> 1.2666667 | L20: =IF(D20<>"",TEXT(D20,"yyyy-mm"),"") -> 2026-04
A21: 17 | B21: EMP002 | C21: =IFERROR(VLOOKUP(B21,'👥 بيانات الموظفين'!B:C,2,0),"") -> فاطمة سعد الزهراني | D21: =DATEVALUE("2026-04-13") -> 46125 | E21: حاضر | F21: =TIMEVALUE("08:03") -> 0.33541667 | G21: =TIMEVALUE("17:01") -> 0.70902778 | H21: =IFERROR(IF(AND(F21<>"",G21<>""),(G21-F21)*24,""),"") -> 8.9666667 | I21: =IFERROR(IF(E21="متأخر",MAX(0,(F21-TIME(8,0,0))*1440),0),0) -> 0 | J21: =IFERROR(IF(AND(ISNUMBER(H21),H21>WorkHoursDay),H21-WorkHoursDay,0),0) -> 0.96666667 | L21: =IF(D21<>"",TEXT(D21,"yyyy-mm"),"") -> 2026-04
A22: 18 | B22: EMP002 | C22: =IFERROR(VLOOKUP(B22,'👥 بيانات الموظفين'!B:C,2,0),"") -> فاطمة سعد الزهراني | D22: =DATEVALUE("2026-04-14") -> 46126 | E22: متأخر | F22: =TIMEVALUE("08:13") -> 0.34236111 | G22: =TIMEVALUE("17:00") -> 0.70833333 | H22: =IFERROR(IF(AND(F22<>"",G22<>""),(G22-F22)*24,""),"") -> 8.7833333 | I22: =IFERROR(IF(E22="متأخر",MAX(0,(F22-TIME(8,0,0))*1440),0),0) -> 13 | J22: =IFERROR(IF(AND(ISNUMBER(H22),H22>WorkHoursDay),H22-WorkHoursDay,0),0) -> 0.78333333 | L22: =IF(D22<>"",TEXT(D22,"yyyy-mm"),"") -> 2026-04
A23: 19 | B23: EMP002 | C23: =IFERROR(VLOOKUP(B23,'👥 بيانات الموظفين'!B:C,2,0),"") -> فاطمة سعد الزهراني | D23: =DATEVALUE("2026-04-15") -> 46127 | E23: حاضر | F23: =TIMEVALUE("07:59") -> 0.33263889 | G23: =TIMEVALUE("17:00") -> 0.70833333 | H23: =IFERROR(IF(AND(F23<>"",G23<>""),(G23-F23)*24,""),"") -> 9.0166667 | I23: =IFERROR(IF(E23="متأخر",MAX(0,(F23-TIME(8,0,0))*1440),0),0) -> 0 | J23: =IFERROR(IF(AND(ISNUMBER(H23),H23>WorkHoursDay),H23-WorkHoursDay,0),0) -> 1.0166667 | L23: =IF(D23<>"",TEXT(D23,"yyyy-mm"),"") -> 2026-04
A24: 20 | B24: EMP002 | C24: =IFERROR(VLOOKUP(B24,'👥 بيانات الموظفين'!B:C,2,0),"") -> فاطمة سعد الزهراني | D24: =DATEVALUE("2026-04-16") -> 46128 | E24: حاضر | F24: =TIMEVALUE("07:58") -> 0.33194444 | G24: =TIMEVALUE("17:01") -> 0.70902778 | H24: =IFERROR(IF(AND(F24<>"",G24<>""),(G24-F24)*24,""),"") -> 9.05 | I24: =IFERROR(IF(E24="متأخر",MAX(0,(F24-TIME(8,0,0))*1440),0),0) -> 0 | J24: =IFERROR(IF(AND(ISNUMBER(H24),H24>WorkHoursDay),H24-WorkHoursDay,0),0) -> 1.05 | L24: =IF(D24<>"",TEXT(D24,"yyyy-mm"),"") -> 2026-04
